Workbook

Sheet Rekapitulace
A1: Název | B1: Hodnota A | C1: Hodnota B
A2: Základní náklady
A3: Dodávka | B3: =0 -> 0
A4: Doprava 0,00%, Přesun 1,00% | B4: =B3 * Parametry!B16 / 100 -> 0 | C4: =B3 * Parametry!B17 / 100 -> 0
A5: Montáž - materiál | C5: =(Rozpočet!F105) + 0 -> 266093.72
A6: Montáž - práce | C6: =0 + (Rozpočet!H105) + 0 -> 168013
A7: Mezisoučet 1 | B7: =B3 + B4 -> 0 | C7: =C3 + C4 + C5 + C6 -> 434106.72
A8: PPV 1,00% z montáže: materiál + práce | C8: =(C5 + C6) * Parametry!B18 / 100 -> 4341.0672
A9: Nátěry | C9: =0 + 0 -> 0
A10: Zemní práce | C10: =(Rozpočet!F145) + (Rozpočet!H145) -> 39349.482
A11: PPV 0,00% z nátěrů a zemních prací | C11: =(C9 + C10) * Parametry!B19 / 100 -> 0
A12: Mezisoučet 2 | B12: =B7 -> 0 | C12: =C7 + C8 + C9 + C10 + C11 -> 477797.27
A13: Dodav. dokumentace 0,00% z mezisoučtu 2 | C13: =(B12 + C12) * Parametry!B20 / 100 -> 0
A14: Rizika a pojištění 0,00% z mezisoučtu 2 | C14: =(B12 + C12) * Parametry!B21 / 100 -> 0
A15: Opravy v záruce 0,00% z mezisoučtu 1 | C15: =(B7 + C7) * Parametry!B22 / 100 -> 0
A16: Základní náklady celkem | C16: =B12 + C12 + C13 + C14 + C15 -> 477797.27
A18: Vedlejší náklady
A19: GZS 3,25% z pravé strany mezisoučtu 2 | C19: =C12 * Parametry!B23 / 100 -> 15528.411
A20: Provozní vlivy 0,00% z pravé strany mezisoučtu 2 | C20: =C12 * Parametry!B24 / 100 -> 0
A21: Vedlejší náklady celkem | C21: =C19 + C20 -> 15528.411
A22: Kompletační činnost | C22: =Parametry!B25 * Parametry!B28 * (C16 * Parametry!B27)^Parametry!B26 -> 0
A24: Náklady celkem bez DPH | C24: =C16 + C21 + C22 -> 493325.68
A26: Součty odstavců | B26: Materiál | C26: Montáž
A27: Elektromontáže | B27: =(Rozpočet!F105) -> 266093.72 | C27: =(Rozpočet!H105) -> 168013
A28: D.2.5.1 - SO31 Areálové rozvody NN a VO | B28: =(Rozpočet!F102) -> 255859.35 | C28: =(Rozpočet!H102) -> 168013
A29: Svítidla | B29: =(Rozpočet!F12) -> 0 | C29: =(Rozpočet!H12) -> 2100
A30: Sloupy VO | B30: =(Rozpočet!F23) -> 38668.251 | C30: =(Rozpočet!H23) -> 14250
A31: Kabely | B31: =(Rozpočet!F35) -> 163993.89 | C31: =(Rozpočet!H35) -> 44640
A32: Kabelové trasy, nosné konstrukce | B32: =(Rozpočet!F43) -> 8575.9488 | C32: =(Rozpočet!H43) -> 7500
A33: Ukončení vodičů | B33: =(Rozpočet!F60) -> 929.78716 | C33: =(Rozpočet!H60) -> 10248
A34: Uzemnění | B34: =(Rozpočet!F80) -> 36414.974 | C34: =(Rozpočet!H80) -> 72275
A35: Ostatní | B35: =(Rozpočet!F93) -> 7276.5 | C35: =(Rozpočet!H93) -> 11700
A36: Revize | B36: =(Rozpočet!F100) -> 0 | C36: =(Rozpočet!H100) -> 5300
A37: Zemní práce | B37: =(Rozpočet!F145) -> 18536.182 | C37: =(Rozpočet!H145) -> 20813.3

Sheet Rozpočet
B1: Název | C1: Mj | D1: Počet | E1: Materiál | F1: Materiál celkem | G1: Montáž | H1: Montáž celkem | I1: Cena | J1: Cena celkem | M1: =Parametry!B33/100*F9+Parametry!B33/100*F10+Parametry!B33/100*F17+Parametry!B33/100*F19+Parametry!B33/100*F21+Parametry!B33/100*F28+Parametry!B33/100*F30+Parametry!B33/100*F31+Parametry!B33/100*F32+Parametry!B33/100*F33+Parametry!B33/100*F39+Parametry!B33/100*F40+Parametry!B33/100*F41+Parametry!B33/100*F49+Parametry!B33/100*F50+Parametry!B33/100*F51+Parametry!B33/100*F53+Parametry!B33/100*F54+Parametry!B33/100*F55+Parametry!B33/100*F56+Parametry!B33/100*F57+Parametry!B33/100*F58+Parametry!B34/100*F66 -> 10632.649 | O1: 1.155 | T1: =O1 -> 1.155
I2: =E2+G2 -> 0 | J2: =F2+H2 -> 0 | N2: Dodávka "A" | O2: Koeficient | P2: Dodávka "C" | S2: Montáž "A" | T2: Koeficient | U2: Montáž "C"
B3: Elektromontáže
I4: =E4+G4 -> 0 | J4: =F4+H4 -> 0
B5: D.2.5.1 - SO31 Areálové rozvody NN a VO
I6: =E6+G6 -> 0 | J6: =F6+H6 -> 0
B7: Svítidla - jen montáž
I8: =E8+G8 -> 0 | J8: =F8+H8 -> 0
B9: CHA1 (X1) -THOME Lighting s.r.o. MOD0007_280W_840_60° MODY 42000lm 280W IP66 4K 60° | C9: ks | D9: 6 | E9: =SUM(P9) -> 0 | F9: =D9*E9 -> 0 | G9: =SUM(S9) -> 350 | H9: =D9*G9 -> 2100 | I9: =E9+G9 -> 350 | J9: =F9+H9 -> 2100 | O9: =$O$1 -> 1.155 | P9: =SUM(N9*O9) -> 0 | S9: 350 | T9: =$T$1 -> 1.155 | U9: =SUM(S9*T9) -> 404.25 | W9: =SUM(N9*D9) -> 0 | X9: =SUM(S9*D9) -> 2100
B10: SL002 Poplatek za recyklaci svítidla | C10: ks | D10: 6 | E10: =SUM(P10) -> 0 | F10: =D10*E10 -> 0 | G10: =SUM(S10) -> 0 | H10: =D10*G10 -> 0 | I10: =E10+G10 -> 0 | J10: =F10+H10 -> 0 | O10: =$O$1 -> 1.155 | P10: =SUM(N10*O10) -> 0 | T10: =$T$1 -> 1.155 | U10: =SUM(S10*T10) -> 0 | W10: =SUM(N10*D10) -> 0 | X10: =SUM(S10*D10) -> 0
I11: =E11+G11 -> 0 | J11: =F11+H11 -> 0 | W11: =SUM(N11*D11) -> 0 | X11: =SUM(S11*D11) -> 0
B12: Svítidla - celkem | F12: =SUM(F8:F11) -> 0 | H12: =SUM(H8:H11) -> 2100 | J12: =SUM(J8:J11) -> 2100 | W12: =SUM(N12*D12) -> 0 | X12: =SUM(S12*D12) -> 0
I13: =E13+G13 -> 0 | J13: =F13+H13 -> 0 | W13: =SUM(N13*D13) -> 0 | X13: =SUM(S13*D13) -> 0
B14: Sloupy VO | W14: =SUM(N14*D14) -> 0 | X14: =SUM(S14*D14) -> 0
I15: =E15+G15 -> 0 | J15: =F15+H15 -> 0 | W15: =SUM(N15*D15) -> 0 | X15: =SUM(S15*D15) -> 0
B16: OSVĚTLOVACÍ STOŽÁR BEZPATICOVÝ | K16: nově | L16: nová cena | M16: původní | W16: =SUM(N16*D16) -> 0 | X16: =SUM(S16*D16) -> 0
B17: JBUD14 14m, stožár silniční, bezpaticový, s přírubou | C17: ks | D17: 3 | E17: =SUM(P17) -> 10487.862 | F17: =D17*E17 -> 31463.586 | G17: =SUM(S17) -> 3600 | H17: =D17*G17 -> 10800 | I17: =E17+G17 -> 14087.862 | J17: =F17+H17 -> 42263.586 | K17: =SUM(D17*L17) -> 43239 | L17: 14413 | M17: =SUM(N17*D17) -> 27241.2 | N17: =SUM([1]Rozpočet!$U$12) -> 9080.4 | O17: =$O$1 -> 1.155 | P17: =SUM(N17*O17) -> 10487.862 | S17: 3600 | T17: =$T$1 -> 1.155 | U17: =SUM(S17*T17) -> 4158 | W17: =SUM(N17*D17) -> 27241.2 | X17: =SUM(S17*D17) -> 10800
B18: VÝLOŽNÍK | K18: =SUM(D18*L18) -> 0 | M18: =SUM(N18*D18) -> 0 | W18: =SUM(N18*D18) -> 0 | X18: =SUM(S18*D18) -> 0
B19: Držák reflektorů, typ TR2-1500-PL (AMAKO) pro dva reflektory | C19: ks | D19: 3 | E19: =SUM(P19) -> 1994.5695 | F19: =D19*E19 -> 5983.7085 | G19: =SUM(S19) -> 600 | H19: =D19*G19 -> 1800 | I19: =E19+G19 -> 2594.5695 | J19: =F19+H19 -> 7783.7085 | K19: =SUM(D19*L19) -> 8223 | L19: 2741 | M19: =SUM(N19*D19) -> 5180.7 | N19: =SUM([1]Rozpočet!$U$14) -> 1726.9 | O19: =$O$1 -> 1.155 | P19: =SUM(N19*O19) -> 1994.5695 | S19: 600 | T19: =$T$1 -> 1.155 | U19: =SUM(S19*T19) -> 693 | W19: =SUM(N19*D19) -> 5180.7 | X19: =SUM(S19*D19) -> 1800
B20: STOŽÁROVÁ VÝZBROJ | K20: =SUM(D20*L20) -> 0 | M20: =SUM(N20*D20) -> 0 | W20: =SUM(N20*D20) -> 0 | X20: =SUM(S20*D20) -> 0
B21: EKM 2035 2xE27, 2x Svorkovnice 4x16 | C21: ks | D21: 3 | E21: =SUM(P21) -> 406.98553 | F21: =D21*E21 -> 1220.9566 | G21: =SUM(S21) -> 550 | H21: =D21*G21 -> 1650 | I21: =E21+G21 -> 956.98553 | J21: =F21+H21 -> 2870.9566 | K21: =SUM(D21*L21) -> 1057.11 | L21: 352.37 | M21: =SUM(N21*D21) -> 1057.1053 | N21: =SUM([1]Rozpočet!$U$16) -> 352.36842 | O21: =$O$1 -> 1.155 | P21: =SUM(N21*O21) -> 406.98553 | S21: 550 | T21: =$T$1 -> 1.155 | U21: =SUM(S21*T21) -> 635.25 | W21: =SUM(N21*D21) -> 1057.1053 | X21: =SUM(S21*D21) -> 1650
I22: =E22+G22 -> 0 | J22: =F22+H22 -> 0 | W22: =SUM(N22*D22) -> 0 | X22: =SUM(S22*D22) -> 0
B23: Sloupy VO - celkem | F23: =SUM(F15:F22) -> 38668.251 | H23: =SUM(H15:H22) -> 14250 | J23: =SUM(J15:J22) -> 52918.251 | K23: =SUM(K17:K22) -> 52519.11 | M23: =SUM(M17:M22) -> 33479.005 | W23: =SUM(N23*D23) -> 0 | X23: =SUM(S23*D23) -> 0
I24: =E24+G24 -> 0 | J24: =F24+H24 -> 0 | W24: =SUM(N24*D24) -> 0 | X24: =SUM(S24*D24) -> 0
B25: Kabely | W25: =SUM(N25*D25) -> 0 | X25: =SUM(S25*D25) -> 0
I26: =E26+G26 -> 0 | J26: =F26+H26 -> 0 | W26: =SUM(N26*D26) -> 0 | X26: =SUM(S26*D26) -> 0
B27: KABEL SILOVÝ,IZOLACE PVC,1kV | W27: =SUM(N27*D27) -> 0 | X27: =SUM(S27*D27) -> 0
B28: AYKY-J 3x120+70 | C28: m | D28: 400 | E28: =SUM(P28) -> 198.198 | F28: =D28*E28 -> 79279.2 | G28: =SUM(S28) -> 45 | H28: =D28*G28 -> 18000 | I28: =E28+G28 -> 243.198 | J28: =F28+H28 -> 97279.2 | N28: =SUM([2]List1!$E$180) -> 171.6 | O28: =$O$1 -> 1.155 | P28: =SUM(N28*O28) -> 198.198 | S28: 45 | T28: =$T$1 -> 1.155 | U28: =SUM(S28*T28) -> 51.975 | W28: =SUM(N28*D28) -> 68640 | X28: =SUM(S28*D28) -> 18000
B29: KABEL SILOVÝ,IZOLACE PVC | W29: =SUM(N29*D29) -> 0 | X29: =SUM(S29*D29) -> 0
B30: CYKY-J 3x1.5 | C30: m | D30: 180 | E30: =SUM(P30) -> 13.495482 | F30: =D30*E30 -> 2429.1868 | G30: =SUM(S30) -> 22 | H30: =D30*G30 -> 3960 | I30: =E30+G30 -> 35.495482 | J30: =F30+H30 -> 6389.1868 | N30: =SUM([2]List1!$E$181) -> 11.6844 | O30: =$O$1 -> 1.155 | P30: =SUM(N30*O30) -> 13.495482 | S30: 22 | T30: =$T$1 -> 1.155 | U30: =SUM(S30*T30) -> 25.41 | W30: =SUM(N30*D30) -> 2103.192 | X30: =SUM(S30*D30) -> 3960
B31: CYKY-J 4x10 | C31: m | D31: 550 | E31: =SUM(P31) -> 111.36926 | F31: =D31*E31 -> 61253.092 | G31: =SUM(S31) -> 28 | H31: =D31*G31 -> 15400 | I31: =E31+G31 -> 139.36926 | J31: =F31+H31 -> 76653.092 | N31: =SUM([2]List1!$E$182) -> 96.4236 | O31: =$O$1 -> 1.155 | P31: =SUM(N31*O31) -> 111.36926 | S31: 28 | T31: =$T$1 -> 1.155 | U31: =SUM(S31*T31) -> 32.34 | W31: =SUM(N31*D31) -> 53032.98 | X31: =SUM(S31*D31) -> 15400
B32: CYKY-J 5x10 | C32: m | D32: 110 | E32: =SUM(P32) -> 141.26112 | F32: =D32*E32 -> 15538.723 | G32: =SUM(S32) -> 28 | H32: =D32*G32 -> 3080 | I32: =E32+G32 -> 169.26112 | J32: =F32+H32 -> 18618.723 | N32: =SUM([2]List1!$E$183) -> 122.304 | O32: =$O$1 -> 1.155 | P32: =SUM(N32*O32) -> 141.26112 | S32: 28 | T32: =$T$1 -> 1.155 | U32: =SUM(S32*T32) -> 32.34 | W32: =SUM(N32*D32) -> 13453.44 | X32: =SUM(S32*D32) -> 3080
B33: CYKY-J 3x4 | C33: m | D33: 150 | E33: =SUM(P33) -> 36.624588 | F33: =D33*E33 -> 5493.6882 | G33: =SUM(S33) -> 28 | H33: =D33*G33 -> 4200 | I33: =E33+G33 -> 64.624588 | J33: =F33+H33 -> 9693.6882 | N33: =SUM([2]List1!$E$184) -> 31.7096 | O33: =$O$1 -> 1.155 | P33: =SUM(N33*O33) -> 36.624588 | S33: 28 | T33: =$T$1 -> 1.155 | U33: =SUM(S33*T33) -> 32.34 | W33: =SUM(N33*D33) -> 4756.44 | X33: =SUM(S33*D33) -> 4200
I34: =E34+G34 -> 0 | J34: =F34+H34 -> 0 | W34: =SUM(N34*D34) -> 0 | X34: =SUM(S34*D34) -> 0
B35: Kabely - celkem | F35: =SUM(F26:F34) -> 163993.89 | H35: =SUM(H26:H34) -> 44640 | J35: =SUM(J26:J34) -> 208633.89 | W35: =SUM(N35*D35) -> 0 | X35: =SUM(S35*D35) -> 0
I36: =E36+G36 -> 0 | J36: =F36+H36 -> 0 | W36: =SUM(N36*D36) -> 0 | X36: =SUM(S36*D36) -> 0
B37: Kabelové trasy, nosné konstrukce | W37: =SUM(N37*D37) -> 0 | X37: =SUM(S37*D37) -> 0
I38: =E38+G38 -> 0 | J38: =F38+H38 -> 0 | W38: =SUM(N38*D38) -> 0 | X38: =SUM(S38*D38) -> 0
B39: KF 09110 TRUBKA KOPOFLEX 110 | C39: m | D39: 20 | E39: =SUM(P39) -> 39.823245 | F39: =D39*E39 -> 796.4649 | G39: =SUM(S39) -> 30 | H39: =D39*G39 -> 600 | I39: =E39+G39 -> 69.823245 | J39: =F39+H39 -> 1396.4649 | N39: =SUM([2]List1!$E$185) -> 34.479 | O39: =$O$1 -> 1.155 | P39: =SUM(N39*O39) -> 39.823245 | S39: 30 | T39: =$T$1 -> 1.155 | U39: =SUM(S39*T39) -> 34.65 | W39: =SUM(N39*D39) -> 689.58 | X39: =SUM(S39*D39) -> 600
B40: KF 09160 TRUBKA KOPOFLEX 160 | C40: m | D40: 90 | E40: =SUM(P40) -> 86.43871 | F40: =D40*E40 -> 7779.4839 | G40: =SUM(S40) -> 40 | H40: =D40*G40 -> 3600 | I40: =E40+G40 -> 126.43871 | J40: =F40+H40 -> 11379.484 | N40: =SUM([1]Rozpočet!$U$34) -> 74.83871 | O40: =$O$1 -> 1.155 | P40: =SUM(N40*O40) -> 86.43871 | S40: 40 | T40: =$T$1 -> 1.155 | U40: =SUM(S40*T40) -> 46.2 | W40: =SUM(N40*D40) -> 6735.4839 | X40: =SUM(S40*D40) -> 3600
...

Sheet Parametry
A1: Název | B1: Hodnota
A2: Nadpis rekapitulace | B2: Seznam prací a dodávek elektrotechnických zařízení
A3: Akce | B3: Prodejna pro dům a zahradu, ulice Lomská, Litvínov
A4: Projekt | B4: D.2.5-1 - SO 31 Areálové rozvody NN a VO
A5: Investor | B5: DEKINVEST, investiční fond s proměnným základním kapitálem, a.s. Tiskařská 257/10, 108 00 Praha 10
A6: Z. č. | B6: 2017-15-02
A7: A. č. | B7: 21458
A8: Smlouva
A9: Vypracoval | B9: Martin Zeman
A10: Kontroloval | B10: Martin Zeman
A11: Datum | B11: 13.12.2021
A12: Zpracovatel | B12: Martin Zeman, Zašovská 256, Valašské Meziříčí
A13: CÚ | B13: 12/2021
A14: Poznámka | B14: Uvedené ceny jsou v Kč a nezahrnují DPH, pokud to není uvedeno.
A16: Doprava dodávek (3,6) % | B16: 0,00
A17: Přesun dodávek (1) % | B17: 1,00
A18: PPV (1 nebo 6) % | B18: 1,00
A19: PPV zemních prací, nátěrů (1) % | B19: 0,00
A20: Dodavat. dokumentace (1 - 1,5) % | B20: 0,00
A21: Rizika a pojištění (1 - 1,5) % | B21: 0,00
... A32: 2. sazba DPH % | B32: 15
A33: Procento PM % 1 | B33: 5
A34: Procento PM % 2 | B34: 1
