Workbook

Sheet Rekapitulace
A1: Název | B1: Hodnota A | C1: Hodnota B
A2: Základní náklady
A3: Dodávka | B3: =0 -> 0
A4: Doprava 3,60%, Přesun 1,00% | B4: =B3 * Parametry!B16 / 100 -> 0 | C4: =B3 * Parametry!B17 / 100 -> 0
A5: Montáž - materiál | C5: =(Rozpočet!F338) + 0 -> 1113373.6
A6: Montáž - práce | C6: =0 + (Rozpočet!I338) + 0 -> 1107439.4
A7: Mezisoučet 1 | B7: =B3 + B4 -> 0 | C7: =C3 + C4 + C5 + C6 -> 2220813
A8: PPV 1,00% z montáže: materiál + práce | C8: =(C5 + C6) * Parametry!B18 / 100 -> 22208.13
A9: Nátěry | C9: =0 + 0 -> 0
A10: Zemní práce | C10: =(Rozpočet!F347) + (Rozpočet!I347) -> 0
A11: PPV 0,00% z nátěrů a zemních prací | C11: =(C9 + C10) * Parametry!B19 / 100 -> 0
A12: Mezisoučet 2 | B12: =B7 -> 0 | C12: =C7 + C8 + C9 + C10 + C11 -> 2243021.1
A13: Dodav. dokumentace 0,00% z mezisoučtu 2 | C13: =(B12 + C12) * Parametry!B20 / 100 -> 0
A14: Rizika a pojištění 0,00% z mezisoučtu 2 | C14: =(B12 + C12) * Parametry!B21 / 100 -> 0
A15: Opravy v záruce 0,00% z mezisoučtu 1 | C15: =(B7 + C7) * Parametry!B22 / 100 -> 0
A16: Základní náklady celkem | C16: =B12 + C12 + C13 + C14 + C15 -> 2243021.1
A18: Vedlejší náklady
A19: GZS 0,00% z pravé strany mezisoučtu 2 | C19: =C12 * Parametry!B23 / 100 -> 0
A20: Provozní vlivy 0,00% z pravé strany mezisoučtu 2 | C20: =C12 * Parametry!B24 / 100 -> 0
A21: Vedlejší náklady celkem | C21: =C19 + C20 -> 0
A22: Kompletační činnost | C22: =Parametry!B25 * Parametry!B28 * (C16 * Parametry!B27)^Parametry!B26 -> 0
A24: Náklady celkem bez DPH | C24: =C16 + C21 + C22 -> 2243021.1
A26: Součty odstavců | B26: Materiál | C26: Montáž
A27: Elektromontáže | B27: =(Rozpočet!F338) -> 1113373.6 | C27: =(Rozpočet!I338) -> 1107439.4
A28: D.1.4.3 - Zařízení silnoproudé elektrotechniky | B28: =(Rozpočet!F335) -> 1091542.7 | C28: =(Rozpočet!I335) -> 1107439.4
A29: Rozvaděče | B29: =(Rozpočet!F16) -> 329706.3 | C29: =(Rozpočet!I16) -> 73898.055
A30: Svítidla | B30: =(Rozpočet!F47) -> 0 | C30: =(Rozpočet!I47) -> 144571.35
A31: Elektrické vytápění | B31: =(Rozpočet!F62) -> 20540.283 | C31: =(Rozpočet!I62) -> 3534.3
A32: Zásuvky, spínače, krabice | B32: =(Rozpočet!F176) -> 123258.02 | C32: =(Rozpočet!I176) -> 128124.15
A33: Ovládací skříně | B33: =(Rozpočet!F182) -> 0 | C33: =(Rozpočet!I182) -> 404.25
A34: Kabely | B34: =(Rozpočet!F209) -> 199506.66 | C34: =(Rozpočet!I209) -> 232468.01
A35: Ukončení vodičů | B35: =(Rozpočet!F228) -> 1548.7942 | C35: =(Rozpočet!I228) -> 77217.525
A36: Kabelové trasy, nosné konstrukce | B36: =(Rozpočet!F270) -> 193117.6 | C36: =(Rozpočet!I270) -> 197135.4
A37: Protipožární zabezpečení | B37: =(Rozpočet!F282) -> 0 | C37: =(Rozpočet!I282) -> 0
A38: Hromosvod | B38: =(Rozpočet!F324) -> 223865.08 | C38: =(Rozpočet!I324) -> 213126.38
A39: Revize | B39: =(Rozpočet!F333) -> 0 | C39: =(Rozpočet!I333) -> 36960
A40: Zemní práce | B40: =(Rozpočet!F347) -> 0 | C40: =(Rozpočet!I347) -> 0

Sheet Rozpočet
A1: Položka DEK | B1: Název | C1: Mj | D1: Počet | E1: Materiál | F1: Materiál celkem | H1: Montáž | I1: Montáž celkem | J1: Cena | K1: Cena celkem | N1: =Parametry!B33/100*F11+Parametry!B34/100*F24+Parametry!B33/100*F26+Parametry!B34/100*F28+Parametry!B33/100*F30+Parametry!B33/100*F32+Parametry!B34/100*F34+Parametry!B34/100*F36+Parametry!B33/100*F37+Parametry!B33/100*F39+Parametry!B34/100*F41+Parametry!B34/100*F43+Parametry!B34/100*F45+Parametry!B34/100*F52+Parametry!B34/100*F53+Parametry!B34/100*F54+Parametry!B34/100*F56+Parametry!B34/100*F58+Parametry!B34/100*F59+Parametry!B34/100*F60+Parametry!B34/100*F67+Parametry!B34/100*F69+Parametry!B34/100*F70 -> 2571.4626 | P1: 1.155 | U1: =P1 -> 1.155
J2: =E2+H2 -> 0 | K2: =F2+I2 -> 0 | N2: =N1+Parametry!B34/100*F71+Parametry!B34/100*F72+Parametry!B34/100*F73+Parametry!B34/100*F75+Parametry!B34/100*F76+Parametry!B34/100*F77+Parametry!B34/100*F79+Parametry!B34/100*F80+Parametry!B34/100*F81+Parametry!B34/100*F83+Parametry!B34/100*F84+Parametry!B34/100*F85+Parametry!B34/100*F87+Parametry!B34/100*F88+Parametry!B34/100*F89+Parametry!B34/100*F91+Parametry!B34/100*F92+Parametry!B34/100*F95+Parametry!B34/100*F96+Parametry!B34/100*F97+Parametry!B34/100*F99+Parametry!B34/100*F100+Parametry!B34/100*F101 -> 4422.3967 | O2: Dodávka "A" | P2: Koeficient | Q2: Dodávka "C" | T2: Montáž "A" | U2: Koeficient | V2: Montáž "C"
B3: Elektromontáže | N3: =N2+Parametry!B34/100*F103+Parametry!B34/100*F104+Parametry!B34/100*F105+Parametry!B34/100*F107+Parametry!B34/100*F109+Parametry!B34/100*F110+Parametry!B34/100*F112+Parametry!B34/100*F114+Parametry!B34/100*F116+Parametry!B34/100*F117+Parametry!B34/100*F118+Parametry!B34/100*F120+Parametry!B34/100*F122+Parametry!B34/100*F123+Parametry!B34/100*F125+Parametry!B34/100*F126+Parametry!B34/100*F127+Parametry!B34/100*F129+Parametry!B34/100*F130+Parametry!B34/100*F131+Parametry!B34/100*F133+Parametry!B34/100*F134 -> 5794.2865
J4: =E4+H4 -> 0 | K4: =F4+I4 -> 0 | N4: =N3+Parametry!B34/100*F135+Parametry!B34/100*F136+Parametry!B34/100*F138+Parametry!B34/100*F139+Parametry!B34/100*F140+Parametry!B34/100*F142+Parametry!B34/100*F143+Parametry!B34/100*F144+Parametry!B34/100*F145+Parametry!B34/100*F147+Parametry!B34/100*F148+Parametry!B34/100*F149+Parametry!B34/100*F150+Parametry!B34/100*F152+Parametry!B34/100*F154+Parametry!B34/100*F156+Parametry!B34/100*F158+Parametry!B34/100*F159+Parametry!B34/100*F160+Parametry!B34/100*F162+Parametry!B34/100*F164+Parametry!B34/100*F165 -> 6160.0582
B5: D.1.4.3 - Zařízení silnoproudé elektrotechniky | N5: =N4+Parametry!B34/100*F166+Parametry!B34/100*F167+Parametry!B34/100*F168+Parametry!B34/100*F171+Parametry!B34/100*F173+Parametry!B34/100*F174+Parametry!B33/100*F187+Parametry!B33/100*F188+Parametry!B33/100*F189+Parametry!B33/100*F190+Parametry!B33/100*F191+Parametry!B33/100*F192+Parametry!B33/100*F193+Parametry!B34/100*F194+Parametry!B34/100*F196+Parametry!B33/100*F198+Parametry!B33/100*F200+Parametry!B33/100*F201+Parametry!B33/100*F202+Parametry!B33/100*F204+Parametry!B33/100*F205+Parametry!B33/100*F206 -> 9368.4792
J6: =E6+H6 -> 0 | K6: =F6+I6 -> 0 | N6: =N5+Parametry!B33/100*F207+Parametry!B33/100*F214+Parametry!B33/100*F215+Parametry!B33/100*F216+Parametry!B33/100*F217+Parametry!B33/100*F218+Parametry!B33/100*F221+Parametry!B33/100*F222+Parametry!B34/100*F225+Parametry!B34/100*F226+Parametry!B34/100*F231+Parametry!B33/100*F235+Parametry!B33/100*F239+Parametry!B33/100*F240+Parametry!B33/100*F241+Parametry!B33/100*F244+Parametry!B33/100*F245+Parametry!B33/100*F246+Parametry!B33/100*F247+Parametry!B33/100*F248+Parametry!B34/100*F249+Parametry!B34/100*F250 -> 11273.849
B7: Rozvaděče | N7: =N6+Parametry!B34/100*F251+Parametry!B33/100*F253+Parametry!B34/100*F255+Parametry!B33/100*F256+Parametry!B33/100*F257+Parametry!B33/100*F258+Parametry!B33/100*F259+Parametry!B33/100*F261+Parametry!B33/100*F262+Parametry!B33/100*F264+Parametry!B33/100*F265+Parametry!B33/100*F267+Parametry!B33/100*F268+Parametry!B33/100*F275+Parametry!B33/100*F276+Parametry!B33/100*F277+Parametry!B33/100*F286+Parametry!B33/100*F287+Parametry!B34/100*F288+Parametry!B34/100*F289+Parametry!B33/100*F290+Parametry!B34/100*F292 -> 15656.509
J8: =E8+H8 -> 0 | K8: =F8+I8 -> 0 | P8: =$P$1 -> 1.155 | Q8: =SUM(P8*O8) -> 0 | U8: =$U$1 -> 1.155 | V8: =SUM(U8*T8) -> 0
B9: Skříňový rozvaděč RH, volně stojící, přívod zdola, vývody shora, prostorová rezerva 30%, dle revize č.1 | C9: ks | D9: 1 | E9: =SUM(Q9) -> 324185.4 | F9: =D9*E9 -> 324185.4 | H9: =SUM(V9) -> 64837.08 | I9: =D9*H9 -> 64837.08 | J9: =E9+H9 -> 389022.48 | K9: =F9+I9 -> 389022.48 | O9: =SUM('[1]CN 177 2015'!$H$16) -> 280680 | P9: =$P$1 -> 1.155 | Q9: =SUM(P9*O9) -> 324185.4 | T9: =SUM(O9*0.2) -> 56136 | U9: =$U$1 -> 1.155 | V9: =SUM(U9*T9) -> 64837.08 | X9: =SUM(O9*D9) -> 280680 | Y9: =SUM(T9*D9) -> 56136
B10: MONTÁŽ ROZVADĚČŮ SKŘÍŇOVÝCH | X10: =SUM(O10*D10) -> 0 | Y10: =SUM(T10*D10) -> 0
B11: do 300 kg | C11: ks | D11: 5 | E11: =SUM(Q11) -> 0 | F11: =D11*E11 -> 0 | H11: =SUM(V11) -> 1386 | I11: =D11*H11 -> 6930 | J11: =E11+H11 -> 1386 | K11: =F11+I11 -> 6930 | P11: =$P$1 -> 1.155 | Q11: =SUM(P11*O11) -> 0 | T11: 1200 | U11: =$U$1 -> 1.155 | V11: =SUM(U11*T11) -> 1386 | X11: =SUM(O11*D11) -> 0 | Y11: =SUM(T11*D11) -> 6000
B12: Nástěnný rozvaděč R1, prostorová rezerva 30%, | C12: ks | D12: 1 | E12: =SUM(Q12) -> 5520.9 | F12: =D12*E12 -> 5520.9 | H12: =SUM(V12) -> 1380.225 | I12: =D12*H12 -> 1380.225 | J12: =E12+H12 -> 6901.125 | K12: =F12+I12 -> 6901.125 | O12: =SUM('[1]CN 177 2015'!$H$17) -> 4780 | P12: =$P$1 -> 1.155 | Q12: =SUM(P12*O12) -> 5520.9 | T12: =SUM(O12*0.25) -> 1195 | U12: =$U$1 -> 1.155 | V12: =SUM(U12*T12) -> 1380.225 | X12: =SUM(O12*D12) -> 4780 | Y12: =SUM(T12*D12) -> 1195
B13: MONTÁŽ ROZVODNIC | X13: =SUM(O13*D13) -> 0 | Y13: =SUM(T13*D13) -> 0
B14: do 50 kg | C14: ks | D14: 1 | E14: =SUM(Q14) -> 0 | F14: =D14*E14 -> 0 | H14: =SUM(V14) -> 750.75 | I14: =D14*H14 -> 750.75 | J14: =E14+H14 -> 750.75 | K14: =F14+I14 -> 750.75 | P14: =$P$1 -> 1.155 | Q14: =SUM(P14*O14) -> 0 | T14: 650 | U14: =$U$1 -> 1.155 | V14: =SUM(U14*T14) -> 750.75 | X14: =SUM(O14*D14) -> 0 | Y14: =SUM(T14*D14) -> 650
J15: =E15+H15 -> 0 | K15: =F15+I15 -> 0 | P15: =$P$1 -> 1.155 | Q15: =SUM(P15*O15) -> 0 | U15: =$U$1 -> 1.155 | V15: =SUM(U15*T15) -> 0 | X15: =SUM(O15*D15) -> 0 | Y15: =SUM(T15*D15) -> 0
B16: Rozvaděče - celkem | F16: =SUM(F8:F15) -> 329706.3 | I16: =SUM(I8:I15) -> 73898.055 | K16: =SUM(K8:K15) -> 403604.36 | X16: =SUM(O16*D16) -> 0 | Y16: =SUM(T16*D16) -> 0
J17: =E17+H17 -> 0 | K17: =F17+I17 -> 0 | X17: =SUM(O17*D17) -> 0 | Y17: =SUM(T17*D17) -> 0
B18: Svítidla | X18: =SUM(O18*D18) -> 0 | Y18: =SUM(T18*D18) -> 0
J19: =E19+H19 -> 0 | K19: =F19+I19 -> 0 | X19: =SUM(O19*D19) -> 0 | Y19: =SUM(T19*D19) -> 0
B20: POZNÁMKA: CENA SVÍTIDEL A PŘESNÉ POČTY NOSNÉHO SYSTÉMU BUDE UPŘESNĚNO FIRMOU THOME | J20: =E20+H20 -> 0 | K20: =F20+I20 -> 0 | X20: =SUM(O20*D20) -> 0 | Y20: =SUM(T20*D20) -> 0
J21: =E21+H21 -> 0 | K21: =F21+I21 -> 0 | X21: =SUM(O21*D21) -> 0 | Y21: =SUM(T21*D21) -> 0
B22: Svítidla hlavní + nouzová, Thome Lighting | C22: sada | D22: 1 | E22: =SUM(Q22) -> 0 | F22: =D22*E22 -> 0 | H22: =SUM(V22) -> 0 | I22: =D22*H22 -> 0 | J22: =E22+H22 -> 0 | K22: =F22+I22 -> 0 | P22: =$P$1 -> 1.155 | Q22: =SUM(P22*O22) -> 0 | U22: =$U$1 -> 1.155 | V22: =SUM(U22*T22) -> 0 | X22: =SUM(O22*D22) -> 0 | Y22: =SUM(T22*D22) -> 0
B23: Montáž modulového osvětlovacího systému se zapojením vodičů, ked světelných zdrojů, délky | X23: =SUM(O23*D23) -> 0 | Y23: =SUM(T23*D23) -> 0
B24: přes 1100 mm | C24: m | D24: 320 | E24: =SUM(Q24) -> 0 | F24: =D24*E24 -> 0 | H24: =SUM(V24) -> 69.3 | I24: =D24*H24 -> 22176 | J24: =E24+H24 -> 69.3 | K24: =F24+I24 -> 22176 | P24: =$P$1 -> 1.155 | Q24: =SUM(P24*O24) -> 0 | T24: 60 | U24: =$U$1 -> 1.155 | V24: =SUM(U24*T24) -> 69.3 | X24: =SUM(O24*D24) -> 0 | Y24: =SUM(T24*D24) -> 19200
B25: Montáž svítidel LED se zapojením vodičů - Modulový systém, A, A2, A2/N13, A3/N13, AS2, AS2/N13 | X25: =SUM(O25*D25) -> 0 | Y25: =SUM(T25*D25) -> 0
B26: 1 zdroj | C26: ks | D26: 137 | E26: =SUM(Q26) -> 0 | F26: =D26*E26 -> 0 | H26: =SUM(V26) -> 334.95 | I26: =D26*H26 -> 45888.15 | J26: =E26+H26 -> 334.95 | K26: =F26+I26 -> 45888.15 | P26: =$P$1 -> 1.155 | Q26: =SUM(P26*O26) -> 0 | T26: 290 | U26: =$U$1 -> 1.155 | V26: =SUM(U26*T26) -> 334.95 | X26: =SUM(O26*D26) -> 0 | Y26: =SUM(T26*D26) -> 39730
B27: Montáž LED svítidel se zapojením vodičů, vestavných - B, B+ | X27: =SUM(O27*D27) -> 0 | Y27: =SUM(T27*D27) -> 0
B28: 1 zdroj | C28: ks | D28: 23 | E28: =SUM(Q28) -> 0 | F28: =D28*E28 -> 0 | H28: =SUM(V28) -> 334.95 | I28: =D28*H28 -> 7703.85 | J28: =E28+H28 -> 334.95 | K28: =F28+I28 -> 7703.85 | T28: 290 | U28: =$U$1 -> 1.155 | V28: =SUM(U28*T28) -> 334.95 | X28: =SUM(O28*D28) -> 0 | Y28: =SUM(T28*D28) -> 6670
B29: Montáž svítidel LED se zapojením vodičů - 600x600mm, D++, D+ | X29: =SUM(O29*D29) -> 0 | Y29: =SUM(T29*D29) -> 0
B30: 1 zdroj | C30: ks | D30: 37 | E30: =SUM(Q30) -> 0 | F30: =D30*E30 -> 0 | H30: =SUM(V30) -> 334.95 | I30: =D30*H30 -> 12393.15 | J30: =E30+H30 -> 334.95 | K30: =F30+I30 -> 12393.15 | T30: 290 | U30: =$U$1 -> 1.155 | V30: =SUM(U30*T30) -> 334.95 | X30: =SUM(O30*D30) -> 0 | Y30: =SUM(T30*D30) -> 10730
B31: Montáž svítidel LED (DALI) se zapojením vodičů - 600x600mm, D1 | X31: =SUM(O31*D31) -> 0 | Y31: =SUM(T31*D31) -> 0
B32: 1 zdroj | C32: ks | D32: 25 | E32: =SUM(Q32) -> 0 | F32: =D32*E32 -> 0 | H32: =SUM(V32) -> 334.95 | I32: =D32*H32 -> 8373.75 | J32: =E32+H32 -> 334.95 | K32: =F32+I32 -> 8373.75 | T32: 290 | U32: =$U$1 -> 1.155 | V32: =SUM(U32*T32) -> 334.95 | X32: =SUM(O32*D32) -> 0 | Y32: =SUM(T32*D32) -> 7250
B33: Montáž LED svítidel se zapojením vodičů průmyslových stropních přisazených, E5, F, F1, H | X33: =SUM(O33*D33) -> 0 | Y33: =SUM(T33*D33) -> 0
B34: 1 zdroj | C34: ks | D34: 67 | E34: =SUM(Q34) -> 0 | F34: =D34*E34 -> 0 | H34: =SUM(V34) -> 334.95 | I34: =D34*H34 -> 22441.65 | J34: =E34+H34 -> 334.95 | K34: =F34+I34 -> 22441.65 | T34: 290 | U34: =$U$1 -> 1.155 | V34: =SUM(U34*T34) -> 334.95 | X34: =SUM(O34*D34) -> 0 | Y34: =SUM(T34*D34) -> 19430
B35: Montáž svítidel výbojkových se zapojením vodičů, průmyslových nebo venkovních, V1 | X35: =SUM(O35*D35) -> 0 | Y35: =SUM(T35*D35) -> 0
B36: na třmen | C36: ks | D36: 4 | E36: =SUM(Q36) -> 0 | F36: =D36*E36 -> 0 | H36: =SUM(V36) -> 519.75 | I36: =D36*H36 -> 2079 | J36: =E36+H36 -> 519.75 | K36: =F36+I36 -> 2079 | T36: 450 | U36: =$U$1 -> 1.155 | V36: =SUM(U36*T36) -> 519.75 | X36: =SUM(O36*D36) -> 0 | Y36: =SUM(T36*D36) -> 1800
B37: K - Nástěnné svítidlo Lucis Izar I LED 16W, l=600mm, bílá | C37: ks | D37: 4 | E37: =SUM(Q37) -> 0 | F37: =D37*E37 -> 0 | H37: =SUM(V37) -> 519.75 | I37: =D37*H37 -> 2079 | J37: =E37+H37 -> 519.75 | K37: =F37+I37 -> 2079 | T37: 450 | U37: =$U$1 -> 1.155 | V37: =SUM(U37*T37) -> 519.75 | X37: =SUM(O37*D37) -> 0 | Y37: =SUM(T37*D37) -> 1800
B38: Montáž svítidel LED se zapojením vodičů - K | X38: =SUM(O38*D38) -> 0 | Y38: =SUM(T38*D38) -> 0
B39: 1 zdroj | C39: ks | D39: 4 | E39: =SUM(Q39) -> 0 | F39: =D39*E39 -> 0 | H39: =SUM(V39) -> 334.95 | I39: =D39*H39 -> 1339.8 | J39: =E39+H39 -> 334.95 | K39: =F39+I39 -> 1339.8 | T39: 290 | U39: =$U$1 -> 1.155 | V39: =SUM(U39*T39) -> 334.95 | X39: =SUM(O39*D39) -> 0 | Y39: =SUM(T39*D39) -> 1160
B40: Montáž LED svítidel se zapojením vodičů, vestavných - N6, N8 | X40: =SUM(O40*D40) -> 0 | Y40: =SUM(T40*D40) -> 0
...

Sheet Parametry
A1: Název | B1: Hodnota
A2: Nadpis rekapitulace | B2: Seznam prací a dodávek elektrotechnických zařízení
A3: Akce | B3: PRODEJNA PRO DŮM A ZAHRADU,_x000D_ ULICE LOMSKÁ. LITVÍNOV
A4: Projekt | B4: D.1.4.3 Zařízení silnoproudé elektrotechniky
A5: Investor | B5: DEKINVEST, investiční fond s proměnným základním kapitálem, a.s. Tiskařská 257/10, 108 00 Praha 10
A6: Z. č. | B6: 2017-24-05
A7: A. č. | B7: 24438
A8: Smlouva | B8: Revize č.2: 28.12.2024 - položka označené červeně
A9: Vypracoval | B9: Martin Zeman
A10: Kontroloval | B10: Martin Zeman
A11: Datum | B11: 10.4.2021
A12: Zpracovatel | B12: Martin Zeman, Zašovská 256, Valašské Meziříčí
... A32: 2. sazba DPH % | B32: 15
A33: Procento PM % 1 | B33: 1
A34: Procento PM % 2 | B34: 5
