Workbook

Sheet Rekapitulace
A1: Název | B1: Hodnota A | C1: Hodnota B
A2: Základní náklady
A3: Dodávka | B3: =0 -> 0
A4: Doprava 3,60%, Přesun 1,00% | B4: =B3 * Parametry!B16 / 100 -> 0 | C4: =B3 * Parametry!B17 / 100 -> 0
A5: Montáž - materiál | C5: =(Rozpočet!F316) + 0 -> 1543166
A6: Montáž - práce | C6: =0 + (Rozpočet!H316) + 0 -> 1961710.4
A7: Mezisoučet 1 | B7: =B3 + B4 -> 0 | C7: =C3 + C4 + C5 + C6 -> 3504876.4
A8: PPV 1,00% z montáže: materiál + práce | C8: =(C5 + C6) * Parametry!B18 / 100 -> #VALUE!
A9: Nátěry | C9: =0 + 0 -> 0
A10: Zemní práce | C10: =(Rozpočet!F325) + (Rozpočet!H325) -> 0
A11: PPV 0,00% z nátěrů a zemních prací | C11: =(C9 + C10) * Parametry!B19 / 100 -> 0
A12: Mezisoučet 2 | B12: =B7 -> 0 | C12: =C7 + C8 + C9 + C10 + C11 -> #VALUE!
A13: Dodav. dokumentace 0,00% z mezisoučtu 2 | C13: =(B12 + C12) * Parametry!B20 / 100 -> #VALUE!
A14: Rizika a pojištění 0,00% z mezisoučtu 2 | C14: =(B12 + C12) * Parametry!B21 / 100 -> #VALUE!
A15: Opravy v záruce 0,00% z mezisoučtu 1 | C15: =(B7 + C7) * Parametry!B22 / 100 -> #VALUE!
A16: Základní náklady celkem | C16: =B12 + C12 + C13 + C14 + C15 -> #VALUE!
A18: Vedlejší náklady
A19: GZS 0,00% z pravé strany mezisoučtu 2 | C19: =C12 * Parametry!B23 / 100 -> #VALUE!
A20: Provozní vlivy 0,00% z pravé strany mezisoučtu 2 | C20: =C12 * Parametry!B24 / 100 -> #VALUE!
A21: Vedlejší náklady celkem | C21: =C19 + C20 -> #VALUE!
A22: Kompletační činnost | C22: =Parametry!B25 * Parametry!B28 * (C16 * Parametry!B27)^Parametry!B26 -> #VALUE!
A24: Náklady celkem bez DPH | C24: =C16 + C21 + C22 -> #VALUE!
A26: Součty odstavců | B26: Materiál | C26: Montáž
A27: Elektromontáže | B27: =(Rozpočet!F316) -> 1543166 | C27: =(Rozpočet!H316) -> 1961710.4
A28: D.1.4.5 - Silnoproudá elektrotechnika | B28: =(Rozpočet!F313) -> 1543166 | C28: =(Rozpočet!H313) -> 1961710.4
A29: Rozvaděče | B29: =(Rozpočet!F14) -> 487255 | C29: =(Rozpočet!H14) -> 109858.8
A30: Svítidla | B30: =(Rozpočet!F48) -> 0 | C30: =(Rozpočet!H48) -> 246089.4
A31: Elektrické vytápění | B31: =(Rozpočet!F66) -> 40855.118 | C31: =(Rozpočet!H66) -> 10572
A32: Zásuvky, spínače, krabice | B32: =(Rozpočet!F140) -> 192719.47 | C32: =(Rozpočet!H140) -> 143568
A33: Ovládací skříně | B33: =(Rozpočet!F144) -> 4542.5 | C33: =(Rozpočet!H144) -> 2040
A34: Kabely | B34: =(Rozpočet!F165) -> 372113.19 | C34: =(Rozpočet!H165) -> 412428
A35: Ukončení vodičů | B35: =(Rozpočet!F179) -> 1959.025 | C35: =(Rozpočet!H179) -> 102132
A36: Kabelové trasy, nosné konstrukce | B36: =(Rozpočet!F220) -> 258302.49 | C36: =(Rozpočet!H220) -> 215071.2
A37: Protipožární zabezpečení | B37: =(Rozpočet!F230) -> 0 | C37: =(Rozpočet!H230) -> 0
A38: Hromosvod a uzemnění | B38: =(Rozpočet!F270) -> 155439.55 | C38: =(Rozpočet!H270) -> 261420
A39: Uzemnění pospojování | B39: =(Rozpočet!F291) -> 20779.646 | C39: =(Rozpočet!H291) -> 41226
A40: Revize | B40: =(Rozpočet!F298) -> 0 | C40: =(Rozpočet!H298) -> 67800
A41: Ostatní | B41: =(Rozpočet!F311) -> 9200 | C41: =(Rozpočet!H311) -> 349505
A42: Zemní práce | B42: =(Rozpočet!F325) -> 0 | C42: =(Rozpočet!H325) -> 0

Sheet Rozpočet
A1: Věta | B1: Název | C1: Mj | D1: Počet | E1: Materiál | F1: Materiál celkem | G1: Montáž | H1: Montáž celkem | I1: Cena | J1: Cena celkem | K1: Poznámka | M1: =Parametry!B33/100*F10+Parametry!B33/100*F13+Parametry!B34/100*F21+Parametry!B33/100*F23+Parametry!B34/100*F25+Parametry!B33/100*F27+Parametry!B33/100*F29+Parametry!B34/100*F31+Parametry!B34/100*F32+Parametry!B34/100*F34+Parametry!B34/100*F36+Parametry!B33/100*F38+Parametry!B33/100*F40+Parametry!B34/100*F42+Parametry!B34/100*F44+Parametry!B34/100*F46+Parametry!B34/100*F47+Parametry!B34/100*F52+Parametry!B34/100*F53+Parametry!B34/100*F54+Parametry!B34/100*F56+Parametry!B34/100*F57+Parametry!B34/100*F58 -> 1388.6595 | O1: 1.15 | T1: 1.2
I2: =E2+G2 -> 0 | J2: =F2+H2 -> 0 | M2: =M1+Parametry!B34/100*F60+Parametry!B34/100*F61+Parametry!B34/100*F62+Parametry!B34/100*F63+Parametry!B34/100*F64+Parametry!B34/100*F65+Parametry!B33/100*F70+Parametry!B33/100*F71+Parametry!B33/100*F72+Parametry!B34/100*F74+Parametry!B33/100*F76+Parametry!B33/100*F77+Parametry!B33/100*F79+Parametry!B33/100*F81+Parametry!B33/100*F82+Parametry!B34/100*F84+Parametry!B34/100*F85+Parametry!B34/100*F87+Parametry!B34/100*F89+Parametry!B34/100*F91+Parametry!B34/100*F92+Parametry!B34/100*F93+Parametry!B33/100*F96 -> 3603.4796 | N2: Dodávka "A" | O2: Koeficient | P2: Dodávka "C" | S2: Montáž "A" | T2: Koeficient | U2: Montáž "C"
B3: Elektromontáže | M3: =M2+Parametry!B33/100*F98+Parametry!B34/100*F100+Parametry!B34/100*F102+Parametry!B34/100*F103+Parametry!B34/100*F104+Parametry!B33/100*F106+Parametry!B34/100*F110+Parametry!B34/100*F111+Parametry!B34/100*F112+Parametry!B34/100*F113+Parametry!B34/100*F114+Parametry!B34/100*F116+Parametry!B34/100*F117+Parametry!B34/100*F118+Parametry!B34/100*F120+Parametry!B33/100*F121+Parametry!B34/100*F122+Parametry!B34/100*F124+Parametry!B33/100*F126+Parametry!B33/100*F128+Parametry!B34/100*F130+Parametry!B33/100*F131 -> 4999.7171
I4: =E4+G4 -> 0 | J4: =F4+H4 -> 0 | M4: =M3+Parametry!B33/100*F132+Parametry!B33/100*F133+Parametry!B33/100*F137+Parametry!B33/100*F138+Parametry!B33/100*F139+Parametry!B34/100*F148+Parametry!B34/100*F149+Parametry!B34/100*F150+Parametry!B34/100*F151+Parametry!B34/100*F152+Parametry!B34/100*F153+Parametry!B34/100*F154+Parametry!B34/100*F155+Parametry!B34/100*F157+Parametry!B33/100*F159+Parametry!B33/100*F161+Parametry!B33/100*F162+Parametry!B34/100*F163+Parametry!B33/100*F164+Parametry!B33/100*F169+Parametry!B33/100*F170+Parametry!B33/100*F171 -> 22844.91
B5: D.1.4.5 - Silnoproudá elektrotechnika | M5: =M4+Parametry!B33/100*F172+Parametry!B33/100*F173+Parametry!B33/100*F176+Parametry!B33/100*F177+Parametry!B33/100*F185+Parametry!B33/100*F189+Parametry!B33/100*F190+Parametry!B33/100*F191+Parametry!B33/100*F194+Parametry!B33/100*F195+Parametry!B33/100*F196+Parametry!B33/100*F197+Parametry!B33/100*F198+Parametry!B34/100*F199+Parametry!B34/100*F200+Parametry!B34/100*F201+Parametry!B33/100*F203+Parametry!B34/100*F205+Parametry!B33/100*F206+Parametry!B33/100*F207+Parametry!B33/100*F208+Parametry!B33/100*F209 -> 25799.279
I6: =E6+G6 -> 0 | J6: =F6+H6 -> 0 | M6: =M5+Parametry!B33/100*F210+Parametry!B33/100*F212+Parametry!B33/100*F213+Parametry!B33/100*F215+Parametry!B33/100*F216+Parametry!B33/100*F218+Parametry!B33/100*F219+Parametry!B33/100*F224+Parametry!B33/100*F225+Parametry!B33/100*F226+Parametry!B33/100*F234+Parametry!B33/100*F235+Parametry!B33/100*F236+Parametry!B33/100*F238+Parametry!B34/100*F240+Parametry!B34/100*F241+Parametry!B34/100*F242+Parametry!B33/100*F245+Parametry!B33/100*F247+Parametry!B33/100*F249+Parametry!B33/100*F250+Parametry!B34/100*F251 -> 28878.948
B7: Rozvaděče | M7: =M6+Parametry!B33/100*F254+Parametry!B33/100*F255+Parametry!B33/100*F257+Parametry!B33/100*F258+Parametry!B33/100*F259+Parametry!B33/100*F260+Parametry!B33/100*F261+Parametry!B33/100*F262+Parametry!B33/100*F263+Parametry!B33/100*F264+Parametry!B33/100*F266+Parametry!B34/100*F269+Parametry!B34/100*F274+Parametry!B34/100*F275+Parametry!B34/100*F276+Parametry!B34/100*F278+Parametry!B34/100*F280+Parametry!B34/100*F282+Parametry!B34/100*F283+Parametry!B34/100*F285+Parametry!B34/100*F287+Parametry!B34/100*F289 -> 30103.646
B8: Skříňový rozvaděč RH, volně stojící, přívod zdola, vývody shora, prostorová rezerva 30% | C8: ks | D8: 1 | E8: =SUM(P8) -> 482218 | F8: =D8*E8 -> 482218 | G8: =SUM(U8) -> 100636.8 | H8: =D8*G8 -> 100636.8 | I8: =E8+G8 -> 582854.8 | J8: =F8+H8 -> 582854.8 | K8: 3x600+2x800+rohx2000x400+sokl IP55/20 | N8: 419320 | O8: =$O$1 -> 1.15 | P8: =SUM(O8*N8) -> 482218 | S8: =SUM(N8*0.2) -> 83864 | T8: =$T$1 -> 1.2 | U8: =SUM(T8*S8) -> 100636.8 | Y8: =SUM(N8*D8) -> 419320 | AA8: =SUM(S8*D8) -> 83864
A9: 7004-19008 | B9: MONTÁŽ ROZVADĚČŮ SKŘÍŇOVÝCH | K9: Rozvaděč RH je zvětšen kvuli prostorové rezervě psané ve VV a doplněn o rohové pole dle dispozic rozvodny ve 2.NP. | Y9: =SUM(N9*D9) -> 0 | AA9: =SUM(S9*D9) -> 0
A10: 7004-19010 | B10: do 300 kg | C10: ks | D10: 5 | E10: =SUM(P10) -> 0 | F10: =D10*E10 -> 0 | G10: =SUM(U10) -> 1440 | H10: =D10*G10 -> 7200 | I10: =E10+G10 -> 1440 | J10: =F10+H10 -> 7200 | S10: 1200 | T10: =$T$1 -> 1.2 | U10: =SUM(T10*S10) -> 1440 | Y10: =SUM(N10*D10) -> 0 | AA10: =SUM(S10*D10) -> 6000
B11: Nástěnný rozvaděč R1, přívod zespodu, vývody shora, prostorová rezerva 30% | C11: ks | D11: 1 | E11: =SUM(P11) -> 5037 | F11: =D11*E11 -> 5037 | G11: =SUM(U11) -> 1314 | H11: =D11*G11 -> 1314 | I11: =E11+G11 -> 6351 | J11: =F11+H11 -> 6351 | N11: 4380 | O11: =$O$1 -> 1.15 | P11: =SUM(O11*N11) -> 5037 | S11: =SUM(N11*0.25) -> 1095 | T11: =$T$1 -> 1.2 | U11: =SUM(T11*S11) -> 1314 | Y11: =SUM(N11*D11) -> 4380 | AA11: =SUM(S11*D11) -> 1095
A12: 7004-19001 | B12: MONTÁŽ ROZVODNIC | Y12: =SUM(N12*D12) -> 0 | AA12: =SUM(S12*D12) -> 0
A13: 7004-19003 | B13: do 50 kg | C13: ks | D13: 1 | E13: =SUM(P13) -> 0 | F13: =D13*E13 -> 0 | G13: =SUM(U13) -> 708 | H13: =D13*G13 -> 708 | I13: =E13+G13 -> 708 | J13: =F13+H13 -> 708 | S13: 590 | T13: =$T$1 -> 1.2 | U13: =SUM(T13*S13) -> 708 | Y13: =SUM(N13*D13) -> 0 | AA13: =SUM(S13*D13) -> 590
B14: Rozvaděče - celkem | F14: =SUM(F8:F13) -> 487255 | H14: =SUM(H8:H13) -> 109858.8 | J14: =SUM(J8:J13) -> 597113.8 | Y14: =SUM(N14*D14) -> 0 | AA14: =SUM(S14*D14) -> 0
I15: =E15+G15 -> 0 | J15: =F15+H15 -> 0 | Y15: =SUM(N15*D15) -> 0 | AA15: =SUM(S15*D15) -> 0
B16: Svítidla | Y16: =SUM(N16*D16) -> 0 | AA16: =SUM(S16*D16) -> 0
B17: POZNÁMKA: CENA SVÍTIDEL A PŘESNÉ POČTY NOSNÉHO SYSTÉMU BUDE UPŘESNĚNO FIRMOU THOME | I17: =E17+G17 -> 0 | J17: =F17+H17 -> 0 | K17: pouze montáž | Y17: =SUM(N17*D17) -> 0 | AA17: =SUM(S17*D17) -> 0
I18: =E18+G18 -> 0 | J18: =F18+H18 -> 0 | Y18: =SUM(N18*D18) -> 0 | AA18: =SUM(S18*D18) -> 0
B19: Svítidla hlavní + nouzová, Thome Lighting | C19: sada | D19: 1 | E19: =SUM(P19) -> 0 | F19: =D19*E19 -> 0 | G19: =SUM(U19) -> 0 | H19: =D19*G19 -> 0 | I19: =E19+G19 -> 0 | J19: =F19+H19 -> 0 | T19: =$T$1 -> 1.2 | U19: =SUM(T19*S19) -> 0 | Y19: =SUM(N19*D19) -> 0 | AA19: =SUM(S19*D19) -> 0
A20: 9998-5113 | B20: Montáž modulového osvětlovacího systému se zapojením vodičů a příslušenství, délky | Y20: =SUM(N20*D20) -> 0 | AA20: =SUM(S20*D20) -> 0
A21: 9998-5115 | B21: přes 1100 mm | C21: m | D21: 540 | E21: =SUM(P21) -> 0 | F21: =D21*E21 -> 0 | G21: =SUM(U21) -> 72 | H21: =D21*G21 -> 38880 | I21: =E21+G21 -> 72 | J21: =F21+H21 -> 38880 | S21: 60 | T21: =$T$1 -> 1.2 | U21: =SUM(T21*S21) -> 72 | Y21: =SUM(N21*D21) -> 0 | AA21: =SUM(S21*D21) -> 32400
A22: 9998-5046 | B22: Montáž svítidel LED se zapojením vodičů - Modulový systém, A, A2, A2/N13, A3/N13 | Y22: =SUM(N22*D22) -> 0 | AA22: =SUM(S22*D22) -> 0
A23: 9998-5047 | B23: 1 zdroj | C23: ks | D23: 231 | E23: =SUM(P23) -> 0 | F23: =D23*E23 -> 0 | G23: =SUM(U23) -> 348 | H23: =D23*G23 -> 80388 | I23: =E23+G23 -> 348 | J23: =F23+H23 -> 80388 | S23: 290 | T23: =$T$1 -> 1.2 | U23: =SUM(T23*S23) -> 348 | Y23: =SUM(N23*D23) -> 0 | AA23: =SUM(S23*D23) -> 66990
A24: 9998-4987 | B24: Montáž LED svítidel se zapojením vodičů, vestavných - B, B1 | Y24: =SUM(N24*D24) -> 0 | AA24: =SUM(S24*D24) -> 0
A25: 9998-4988 | B25: 1 zdroj | C25: ks | D25: 40 | E25: =SUM(P25) -> 0 | F25: =D25*E25 -> 0 | G25: =SUM(U25) -> 348 | H25: =D25*G25 -> 13920 | I25: =E25+G25 -> 348 | J25: =F25+H25 -> 13920 | S25: 290 | T25: =$T$1 -> 1.2 | U25: =SUM(T25*S25) -> 348 | Y25: =SUM(N25*D25) -> 0 | AA25: =SUM(S25*D25) -> 11600
A26: 9998-5046 | B26: Montáž svítidel LED (DALI) se zapojením vodičů - 600x600mm, D2 | Y26: =SUM(N26*D26) -> 0 | AA26: =SUM(S26*D26) -> 0
A27: 9998-5047 | B27: 1 zdroj | C27: ks | D27: 43 | E27: =SUM(P27) -> 0 | F27: =D27*E27 -> 0 | G27: =SUM(U27) -> 348 | H27: =D27*G27 -> 14964 | I27: =E27+G27 -> 348 | J27: =F27+H27 -> 14964 | K27: kalkulováno bez výřezů do SDK | S27: 290 | T27: =$T$1 -> 1.2 | U27: =SUM(T27*S27) -> 348 | Y27: =SUM(N27*D27) -> 0 | AA27: =SUM(S27*D27) -> 12470
A28: 9998-5046 | B28: Montáž svítidel LED se zapojením vodičů - 600x600mm, D3 | Y28: =SUM(N28*D28) -> 0 | AA28: =SUM(S28*D28) -> 0
A29: 9998-5047 | B29: 1 zdroj | C29: ks | D29: 64 | E29: =SUM(P29) -> 0 | F29: =D29*E29 -> 0 | G29: =SUM(U29) -> 348 | H29: =D29*G29 -> 22272 | I29: =E29+G29 -> 348 | J29: =F29+H29 -> 22272 | K29: kalkulováno bez výřezů do SDK | S29: 290 | T29: =$T$1 -> 1.2 | U29: =SUM(T29*S29) -> 348 | Y29: =SUM(N29*D29) -> 0 | AA29: =SUM(S29*D29) -> 18560
A30: 9998-5046 | B30: Montáž LED svítidel se zapojením vodičů průmyslových stropních přisazených, E, Ex, F, Fx | Y30: =SUM(N30*D30) -> 0 | AA30: =SUM(S30*D30) -> 0
A31: 9998-5048 | B31: 1 zdroj | C31: ks | D31: 34 | E31: =SUM(P31) -> 0 | F31: =D31*E31 -> 0 | G31: =SUM(U31) -> 348 | H31: =D31*G31 -> 11832 | I31: =E31+G31 -> 348 | J31: =F31+H31 -> 11832 | S31: 290 | T31: =$T$1 -> 1.2 | U31: =SUM(T31*S31) -> 348 | Y31: =SUM(N31*D31) -> 0 | AA31: =SUM(S31*D31) -> 9860
A32: 9998-5048 | B32: 1 zdroj - venkovní mytí | C32: ks | D32: 2 | E32: =SUM(P32) -> 0 | F32: =D32*E32 -> 0 | G32: =SUM(U32) -> 420 | H32: =D32*G32 -> 840 | I32: =E32+G32 -> 420 | J32: =F32+H32 -> 840 | S32: 350 | T32: =$T$1 -> 1.2 | U32: =SUM(T32*S32) -> 420 | Y32: =SUM(N32*D32) -> 0 | AA32: =SUM(S32*D32) -> 700
A33: 9998-5046 | B33: Montáž LED svítidel se zapojením vodičů průmyslových stropních přisazených, H | Y33: =SUM(N33*D33) -> 0 | AA33: =SUM(S33*D33) -> 0
A34: 9998-5048 | B34: 1 zdroj | C34: ks | D34: 48 | E34: =SUM(P34) -> 0 | F34: =D34*E34 -> 0 | G34: =SUM(U34) -> 348 | H34: =D34*G34 -> 16704 | I34: =E34+G34 -> 348 | J34: =F34+H34 -> 16704 | S34: 290 | T34: =$T$1 -> 1.2 | U34: =SUM(T34*S34) -> 348 | Y34: =SUM(N34*D34) -> 0 | AA34: =SUM(S34*D34) -> 13920
A35: 9998-5073 | B35: Montáž svítidel výbojkových se zapojením vodičů, průmyslových nebo venkovních, V1 | Y35: =SUM(N35*D35) -> 0 | AA35: =SUM(S35*D35) -> 0
A36: 9998-5075 | B36: na třmen | C36: ks | D36: 6 | E36: =SUM(P36) -> 0 | F36: =D36*E36 -> 0 | G36: =SUM(U36) -> 540 | H36: =D36*G36 -> 3240 | I36: =E36+G36 -> 540 | J36: =F36+H36 -> 3240 | S36: 450 | T36: =$T$1 -> 1.2 | U36: =SUM(T36*S36) -> 540 | Y36: =SUM(N36*D36) -> 0 | AA36: =SUM(S36*D36) -> 2700
A37: 9998-5073 | B37: Svítidlo do soc. zařízení | Y37: =SUM(N37*D37) -> 0 | AA37: =SUM(S37*D37) -> 0
A38: 3002-2 | B38: K - Nástěnné svítidlo Lucis Izar I LED 16W, l=600mm, bílá | C38: ks | D38: 5 | E38: =SUM(P38) -> 0 | F38: =D38*E38 -> 0 | G38: =SUM(U38) -> 348 | H38: =D38*G38 -> 1740 | I38: =E38+G38 -> 348 | J38: =F38+H38 -> 1740 | S38: 290 | T38: =$T$1 -> 1.2 | U38: =SUM(T38*S38) -> 348 | Y38: =SUM(N38*D38) -> 0 | AA38: =SUM(S38*D38) -> 1450
A39: 9998-5046 | B39: Montáž svítidel LED se zapojením vodičů - K | Y39: =SUM(N39*D39) -> 0 | AA39: =SUM(S39*D39) -> 0
A40: 9998-5047 | B40: 1 zdroj | C40: ks | D40: 5 | E40: =SUM(P40) -> 0 | F40: =D40*E40 -> 0 | G40: =SUM(U40) -> 348 | H40: =D40*G40 -> 1740 | I40: =E40+G40 -> 348 | J40: =F40+H40 -> 1740 | S40: 290 | T40: =$T$1 -> 1.2 | U40: =SUM(T40*S40) -> 348 | Y40: =SUM(N40*D40) -> 0 | AA40: =SUM(S40*D40) -> 1450
...

Sheet Parametry
A1: Název | B1: Hodnota
A2: Nadpis rekapitulace | B2: Seznam prací a dodávek elektrotechnických zařízení
A3: Akce | B3: Prodejna pro dům a zahradu, Cheb, ul. Ke Hřbitovu
A4: Projekt | B4: D.1.4.5 Silnoproudá elektrotechnika
A5: Investor | B5: DEKINVEST, investiční fond s proměnným základním kapitálem, a.s. Tiskařská 257/10, 108 00 Praha 10
A6: Z. č. | B6: 2021-34-05
A7: A. č. | B7: 24510
A8: Smlouva
A9: Vypracoval | B9: Martin Zeman
A10: Kontroloval | B10: Martin Zeman
A11: Datum | B11: 28.3.2024
A12: Zpracovatel | B12: Martin Zeman, Zašovská 256, Valašské Meziříčí
A13: CÚ | B13: 03/2024
A14: Poznámka | B14: Uvedené ceny jsou v Kč a nezahrnují DPH, pokud to není uvedeno.
A16: Doprava dodávek (3,6) % | B16: 3,60
A17: Přesun dodávek (1) % | B17: 1,00
A18: PPV (1 nebo 6) % | B18: 1,00
A19: PPV zemních prací, nátěrů (1) % | B19: 0,00
A20: Dodavat. dokumentace (1 - 1,5) % | B20: 0,00
A21: Rizika a pojištění (1 - 1,5) % | B21: 0,00
... A32: 2. sazba DPH % | B32: 15
A33: Procento PM % 1 | B33: 1
A34: Procento PM % 2 | B34: 5
