Workbook
Name _dph1: #REF!
Name _dph2: #REF!
Name _dph3: #REF!
Name _pol1: SLP_R1!#REF!
Name _pol2: SLP_R1!#REF!
Name _pol3: SLP_R1!#REF!
Name footer: #REF!
Name footer2: SLP_R1!#REF!
Name head1: #REF!
Name Header: #REF!
Name Header2: SLP_R1!#REF!
Name Hlava1: #REF!
Name Hlava2: #REF!
Name Hlava3: #REF!
Name Hlava4: #REF!
Name polbezcen1: SLP_R1!#REF!
Name polcen2: SLP_R1!#REF!
Name polcen3: SLP_R1!#REF!
Name Poznamka: #REF!
Name ZakHead: #REF!

Sheet REK
A1: ČESKÝ TĚŠÍN - PRODEJNA PRO DŮM A ZAHRADU
F2: Tady měnit procenta
H3: Dodatečné náklad
A4: D.1.4.4 Zařízení silnoproudé elektrotechniky | B4: =SIL!J393 -> 3484979.1 | G4: plošiny | H4: -120000
A5: D.1.4.5 Zařízení slaboproudé elektrotechniky | B5: =SLP_R1!I348 -> 1990626.1 | F5: 1.149 | G5: Buňkoviště | H5: -60000
A6: D.10, SO44 - Areálové rozvody NN a VO | B6: ='NN + VO'!J168 -> 529694.11
A7: D.11 SO45 - Přípojka VN | B7: ='Přípojka VN + TS'!J114 -> 0
E8: Nákladová cena | F8: % zisk | G8: zisk úspory | I8: Zisk celkem | J8: vyjádřeno v procentech
A9: celkem bez DPH | B9: =SUM(B4:B8) -> 6005299.3 | E9: =B9/SIL!O1 -> 5226544.2 | F9: =B9-E9 -> 778755.08 | G9: =SIL!L394+'NN + VO'!L172+SLP_R0!K287 -> 555600.45 | H9: =SUM(H4:H7) -> -180000 | I9: =F9+G9+H9 -> 1154355.5 | J9: =I9/B9 -> 0.19222282
A12: MaR | B12: =#REF! -> #REF!
A15: V otevřených částech Prodejny (tam, kde není podhled) použít závěsný lankový systém např. Skygrip/Walraven. Prosím o jeho poptání a zapracování do CN.
A16: Jiří Chovančík
A17: 775017710
A18: j.chovancik@skygrip.cz
A24: požadovaná cena za Litvínov + Mimoň je: | B24: 11200000
A26: cena za Litvínov je: | B26: =B24-B9 -> 5194700.7 | E26: 5000000
E27: =E26/B26 -> 0.96251935

Sheet SIL
B1: Název | C1: Mj | D1: Počet | E1: Materiál | F1: Materiál celkem | G1: Montáž | H1: Montáž celkem | I1: Cena | J1: Cena celkem | K1: Poznámka | M1: =[1]Parametry!B33/100*F10+[1]Parametry!B33/100*F13+[1]Parametry!B34/100*F21+[1]Parametry!B33/100*F23+[1]Parametry!B34/100*F25+[1]Parametry!B33/100*F27+[1]Parametry!B33/100*F29+[1]Parametry!B34/100*F32+[1]Parametry!B34/100*#REF!+[1]Parametry!B34/100*F120+[1]Parametry!B34/100*F122+[1]Parametry!B33/100*F124+[1]Parametry!B33/100*F126+[1]Parametry!B34/100*F128+[1]Parametry!B34/100*F130+[1]Parametry!B34/100*F132+[1]Parametry!B34/100*F133+[1]Parametry!B34/100*F138+[1]Parametry!B34/100*F139+[1]Parametry!B34/100*F140+[1]Parametry!B34/100*F142+[1]Parametry!B34/100*F143+[1]Parametry!B34/100*F144 -> #REF! | O1: =REK!F5 -> 1.149 | T1: =SUM(O1) -> 1.149
M2: =M1+[1]Parametry!B34/100*F146+[1]Parametry!B34/100*F147+[1]Parametry!B34/100*F148+[1]Parametry!B34/100*F149+[1]Parametry!B34/100*F150+[1]Parametry!B34/100*F151+[1]Parametry!B33/100*F156+[1]Parametry!B33/100*F157+[1]Parametry!B33/100*F158+[1]Parametry!B34/100*F160+[1]Parametry!B33/100*F162+[1]Parametry!B33/100*F163+[1]Parametry!B33/100*F165+[1]Parametry!B33/100*F167+[1]Parametry!B33/100*F168+[1]Parametry!B34/100*F170+[1]Parametry!B34/100*F171+[1]Parametry!B34/100*F173+[1]Parametry!B34/100*F175+[1]Parametry!B34/100*F177+[1]Parametry!B34/100*F178+[1]Parametry!B34/100*F179+[1]Parametry!B33/100*F182 -> #REF! | N2: Dodávka "A" | O2: Koeficient | P2: Dodávka "C" | S2: Montáž "A" | T2: Koeficient | U2: Montáž "C"
B3: Dodávky | M3: =M2+[1]Parametry!B33/100*F184+[1]Parametry!B34/100*F186+[1]Parametry!B34/100*F188+[1]Parametry!B34/100*F189+[1]Parametry!B34/100*F190+[1]Parametry!B33/100*F192+[1]Parametry!B34/100*F196+[1]Parametry!B34/100*F197+[1]Parametry!B34/100*F198+[1]Parametry!B34/100*F199+[1]Parametry!B34/100*F200+[1]Parametry!B34/100*F202+[1]Parametry!B34/100*F203+[1]Parametry!B34/100*F204+[1]Parametry!B34/100*F206+[1]Parametry!B33/100*F207+[1]Parametry!B34/100*F208+[1]Parametry!B34/100*F210+[1]Parametry!B33/100*F212+[1]Parametry!B33/100*F214+[1]Parametry!B34/100*F216+[1]Parametry!B33/100*F217 -> #REF!
M4: =M3+[1]Parametry!B33/100*F218+[1]Parametry!B33/100*F219+[1]Parametry!B33/100*F223+[1]Parametry!B33/100*F224+[1]Parametry!B33/100*F225+[1]Parametry!B34/100*F234+[1]Parametry!B34/100*F235+[1]Parametry!B34/100*F236+[1]Parametry!B34/100*F237+[1]Parametry!B34/100*F238+[1]Parametry!B34/100*F239+[1]Parametry!B34/100*F240+[1]Parametry!B34/100*F241+[1]Parametry!B34/100*F243+[1]Parametry!B33/100*F245+[1]Parametry!B33/100*F247+[1]Parametry!B33/100*F248+[1]Parametry!B34/100*F249+[1]Parametry!B33/100*F250+[1]Parametry!B33/100*F255+[1]Parametry!B33/100*F256+[1]Parametry!B33/100*F257 -> #REF!
B5: Svítidla | M5: =M4+[1]Parametry!B33/100*F258+[1]Parametry!B33/100*F259+[1]Parametry!B33/100*F262+[1]Parametry!B33/100*F263+[1]Parametry!B33/100*F271+[1]Parametry!B33/100*F275+[1]Parametry!B33/100*F276+[1]Parametry!B33/100*F277+[1]Parametry!B33/100*F280+[1]Parametry!B33/100*F281+[1]Parametry!B33/100*F282+[1]Parametry!B33/100*F283+[1]Parametry!B33/100*F284+[1]Parametry!B34/100*F285+[1]Parametry!B34/100*F286+[1]Parametry!B34/100*F287+[1]Parametry!B33/100*F289+[1]Parametry!B34/100*F291+[1]Parametry!B33/100*F292+[1]Parametry!B33/100*F293+[1]Parametry!B33/100*F294+[1]Parametry!B33/100*F295 -> #REF!
M6: =M5+[1]Parametry!B33/100*F296+[1]Parametry!B33/100*F298+[1]Parametry!B33/100*F299+[1]Parametry!B33/100*F301+[1]Parametry!B33/100*F302+[1]Parametry!B33/100*F304+[1]Parametry!B33/100*F305+[1]Parametry!B33/100*F310+[1]Parametry!B33/100*F311+[1]Parametry!B33/100*F312+[1]Parametry!B33/100*F320+[1]Parametry!B33/100*F321+[1]Parametry!B33/100*F322+[1]Parametry!B33/100*F324+[1]Parametry!B34/100*F326+[1]Parametry!B34/100*F327+[1]Parametry!B34/100*F328+[1]Parametry!B33/100*F331+[1]Parametry!B33/100*F333+[1]Parametry!B33/100*F335+[1]Parametry!B33/100*F336+[1]Parametry!B34/100*F337 -> #REF!
B7: Svítidla | M7: =M6+[1]Parametry!B33/100*F340+[1]Parametry!B33/100*F341+[1]Parametry!B33/100*F343+[1]Parametry!B33/100*F344+[1]Parametry!B33/100*F345+[1]Parametry!B33/100*F346+[1]Parametry!B33/100*F347+[1]Parametry!B33/100*F348+[1]Parametry!B33/100*F349+[1]Parametry!B33/100*F350+[1]Parametry!B33/100*F352+[1]Parametry!B34/100*F355+[1]Parametry!B34/100*F360+[1]Parametry!B34/100*F361+[1]Parametry!B34/100*F362+[1]Parametry!B34/100*F364+[1]Parametry!B34/100*F366+[1]Parametry!B34/100*F368+[1]Parametry!B34/100*F369+[1]Parametry!B34/100*F371+[1]Parametry!B34/100*F373+[1]Parametry!B34/100*F375 -> #REF!
B8: POZNÁMKA: POČET SVÍTIDEL, CENA, BUDE UPŘESNĚN FIRMOU THOME | O8: =$O$1 -> 1.149 | P8: =SUM(O8*N8) -> 0 | Q8: =SUM(N8*D8) -> 0 | T8: =$T$1 -> 1.149 | U8: =SUM(T8*S8) -> 0 | V8: =SUM(S8*D8) -> 0
B9: B - THOME Lighting s.r.o. CIR0014 CirkLED 24W 2200lm IP44 4K | C9: ks | D9: 1 | E9: =SUM(P9) -> 0 | F9: =D9*E9 -> 0 | G9: =SUM(U9) -> 333.21 | H9: =D9*G9 -> 333.21 | I9: =E9+G9 -> 333.21 | J9: =F9+H9 -> 333.21 | O9: =$O$1 -> 1.149 | P9: =SUM(O9*N9) -> 0 | Q9: =SUM(N9*D9) -> 0 | S9: 290 | T9: =$T$1 -> 1.149 | U9: =SUM(T9*S9) -> 333.21 | V9: =SUM(S9*D9) -> 290
B10: B1 - THOME Lighting s.r.o. CIR0013 CirkLED 18W 1600lm IP44 4K | C10: ks | D10: 20 | E10: =SUM(P10) -> 0 | F10: =D10*E10 -> 0 | G10: =SUM(U10) -> 333.21 | H10: =D10*G10 -> 6664.2 | I10: =E10+G10 -> 333.21 | J10: =F10+H10 -> 6664.2 | O10: =$O$1 -> 1.149 | P10: =SUM(O10*N10) -> 0 | Q10: =SUM(N10*D10) -> 0 | S10: 290 | T10: =$T$1 -> 1.149 | U10: =SUM(T10*S10) -> 333.21 | V10: =SUM(S10*D10) -> 5800
B11: D1 - THOME Lighting s.r.o. XED046 XEDO LED PANEL 3600lm 36W IP40 4K 600x600 UGR DALI | C11: ks | D11: 12 | E11: =SUM(P11) -> 0 | F11: =D11*E11 -> 0 | G11: =SUM(U11) -> 402.15 | H11: =D11*G11 -> 4825.8 | I11: =E11+G11 -> 402.15 | J11: =F11+H11 -> 4825.8 | O11: =$O$1 -> 1.149 | P11: =SUM(O11*N11) -> 0 | Q11: =SUM(N11*D11) -> 0 | S11: 350 | T11: =$T$1 -> 1.149 | U11: =SUM(T11*S11) -> 402.15 | V11: =SUM(S11*D11) -> 4200
B12: F8 - THOME lighting s.r.o. SIN0054 ACQUEX °8000lm 55W IP66 4K ATEX 1,5m | C12: ks | D12: 157 | E12: =SUM(P12) -> 0 | F12: =D12*E12 -> 0 | G12: =SUM(U12) -> 333.21 | H12: =D12*G12 -> 52313.97 | I12: =E12+G12 -> 333.21 | J12: =F12+H12 -> 52313.97 | O12: =$O$1 -> 1.149 | P12: =SUM(O12*N12) -> 0 | Q12: =SUM(N12*D12) -> 0 | S12: 290 | T12: =$T$1 -> 1.149 | U12: =SUM(T12*S12) -> 333.21 | V12: =SUM(S12*D12) -> 45530
B13: CH1 (H1) - THOME Lighting s.r.o. MOD0007_280W_840_60° MODY 42000lm 280W IP66 4K 60° | C13: ks | D13: 5 | E13: =SUM(P13) -> 0 | F13: =D13*E13 -> 0 | G13: =SUM(U13) -> 333.21 | H13: =D13*G13 -> 1666.05 | I13: =E13+G13 -> 333.21 | J13: =F13+H13 -> 1666.05 | O13: =$O$1 -> 1.149 | P13: =SUM(O13*N13) -> 0 | Q13: =SUM(N13*D13) -> 0 | S13: 290 | T13: =$T$1 -> 1.149 | U13: =SUM(T13*S13) -> 333.21 | V13: =SUM(S13*D13) -> 1450
B14: V - THOME Lighting s.r.o. TIT2012_69 TITANIA 2G 7800lm 57W IP65 4K třmen | C14: ks | D14: 7 | E14: =SUM(P14) -> 0 | F14: =D14*E14 -> 0 | G14: =SUM(U14) -> 333.21 | H14: =D14*G14 -> 2332.47 | I14: =E14+G14 -> 333.21 | J14: =F14+H14 -> 2332.47 | O14: =$O$1 -> 1.149 | P14: =SUM(O14*N14) -> 0 | Q14: =SUM(N14*D14) -> 0 | S14: 290 | T14: =$T$1 -> 1.149 | U14: =SUM(T14*S14) -> 333.21 | V14: =SUM(S14*D14) -> 2030
B15: SL002 Poplatek za recyklaci svítidla | C15: ks | D15: 202 | E15: =SUM(P15) -> 0 | F15: =D15*E15 -> 0 | G15: =SUM(U15) -> 0 | H15: =D15*G15 -> 0 | I15: =E15+G15 -> 0 | J15: =F15+H15 -> 0 | O15: =$O$1 -> 1.149 | P15: =SUM(O15*N15) -> 0 | Q15: =SUM(N15*D15) -> 0 | T15: =$T$1 -> 1.149 | U15: =SUM(T15*S15) -> 0 | V15: =SUM(S15*D15) -> 0
B16: Svítidla - celkem | F16: =SUM(F8:F15) -> 0 | H16: =SUM(H8:H15) -> 68135.7 | J16: =SUM(J8:J15) -> 68135.7 | Q16: =SUM(N16*D16) -> 0 | V16: =SUM(S16*D16) -> 0
Q17: =SUM(N17*D17) -> 0 | V17: =SUM(S17*D17) -> 0
B18: Nouzová svítidla | Q18: =SUM(N18*D18) -> 0 | V18: =SUM(S18*D18) -> 0
B19: POZNÁMKA: POČET SVÍTIDEL, CENA, BUDE UPŘESNĚN FIRMOU THOME | Q19: =SUM(N19*D19) -> 0 | V19: =SUM(S19*D19) -> 0
B20: P1 - TMT P1_TMT0066 ONTEC G E1B 101 M/AT/Grey_exit | C20: ks | D20: 6 | E20: =SUM(P20) -> 0 | F20: =D20*E20 -> 0 | G20: =SUM(U20) -> 333.21 | H20: =D20*G20 -> 1999.26 | I20: =E20+G20 -> 333.21 | J20: =F20+H20 -> 1999.26 | O20: =$O$1 -> 1.149 | P20: =SUM(O20*N20) -> 0 | Q20: =SUM(N20*D20) -> 0 | S20: 290 | T20: =$T$1 -> 1.149 | U20: =SUM(T20*S20) -> 333.21 | V20: =SUM(S20*D20) -> 1740
B21: N8 - TMT N8_TMT0003 ITECH M2 302 M/AT/White_zapuštěné | C21: ks | D21: 1 | E21: =SUM(P21) -> 0 | F21: =D21*E21 -> 0 | G21: =SUM(U21) -> 333.21 | H21: =D21*G21 -> 333.21 | I21: =E21+G21 -> 333.21 | J21: =F21+H21 -> 333.21 | O21: =$O$1 -> 1.149 | P21: =SUM(O21*N21) -> 0 | Q21: =SUM(N21*D21) -> 0 | S21: 290 | T21: =$T$1 -> 1.149 | U21: =SUM(T21*S21) -> 333.21 | V21: =SUM(S21*D21) -> 290
B22: N20 - VYRTYCH a.s. BASET-Em-LED-350-4K, 1h Emergency lighting | C22: ks | D22: 37 | E22: =SUM(P22) -> 0 | F22: =D22*E22 -> 0 | G22: =SUM(U22) -> 333.21 | H22: =D22*G22 -> 12328.77 | I22: =E22+G22 -> 333.21 | J22: =F22+H22 -> 12328.77 | O22: =$O$1 -> 1.149 | P22: =SUM(O22*N22) -> 0 | Q22: =SUM(N22*D22) -> 0 | S22: 290 | T22: =$T$1 -> 1.149 | U22: =SUM(T22*S22) -> 333.21 | V22: =SUM(S22*D22) -> 10730
B23: SL002 Poplatek za recyklaci svítidla | C23: ks | D23: 44 | E23: =SUM(P23) -> 0 | F23: =D23*E23 -> 0 | G23: =SUM(U23) -> 0 | H23: =D23*G23 -> 0 | I23: =E23+G23 -> 0 | J23: =F23+H23 -> 0 | O23: =$O$1 -> 1.149 | P23: =SUM(O23*N23) -> 0 | Q23: =SUM(N23*D23) -> 0 | T23: =$T$1 -> 1.149 | U23: =SUM(T23*S23) -> 0 | V23: =SUM(S23*D23) -> 0
B24: Nouzová svítidla - celkem | F24: =SUM(F19:F23) -> 0 | H24: =SUM(H19:H23) -> 14661.24 | J24: =SUM(J19:J23) -> 14661.24 | Q24: =SUM(N24*D24) -> 0 | V24: =SUM(S24*D24) -> 0
Q25: =SUM(N25*D25) -> 0 | V25: =SUM(S25*D25) -> 0
B26: Svítidla - celkem | F26: =SUM(F6,F8:F15,F17,F19:F23,F25:F25) -> 0 | H26: =SUM(H6,H8:H15,H17,H19:H23,H25:H25) -> 82796.94 | J26: =SUM(J6,J8:J15,J17,J19:J23,J25:J25) -> 82796.94 | Q26: =SUM(N26*D26) -> 0 | V26: =SUM(S26*D26) -> 0
Q27: =SUM(N27*D27) -> 0 | V27: =SUM(S27*D27) -> 0
B28: Dodávky - celkem | F28: =SUM(F4,F6,F8:F15,F17,F19:F23,F25,F27:F27) -> 0 | H28: =SUM(H4,H6,H8:H15,H17,H19:H23,H25,H27:H27) -> 82796.94 | J28: =SUM(J4,J6,J8:J15,J17,J19:J23,J25,J27:J27) -> 82796.94 | Q28: =SUM(N28*D28) -> 0 | V28: =SUM(S28*D28) -> 0
Q29: =SUM(N29*D29) -> 0 | V29: =SUM(S29*D29) -> 0
B30: Elektromontáže | Q30: =SUM(N30*D30) -> 0 | V30: =SUM(S30*D30) -> 0
Q31: =SUM(N31*D31) -> 0 | V31: =SUM(S31*D31) -> 0
B32: D.1.4.4 - Zařízení silnoproudé elektrotechniky | Q32: =SUM(N32*D32) -> 0 | V32: =SUM(S32*D32) -> 0
Q33: =SUM(N33*D33) -> 0 | V33: =SUM(S33*D33) -> 0
B34: Rozváděč RH1 | Q34: =SUM(N34*D34) -> 0 | V34: =SUM(S34*D34) -> 0
Q35: =SUM(N35*D35) -> 0 | V35: =SUM(S35*D35) -> 0
B36: Rozváděč volně stojící 3x800x2000x400+100podstavec, IP65/20, dle výkresu č. D.1.4.4.11 | C36: ks | D36: 1 | E36: =SUM(P36) -> 423050.31 | F36: =D36*E36 -> 423050.31 | G36: =SUM(U36) -> 88840.565 | H36: =D36*G36 -> 88840.565 | I36: =E36+G36 -> 511890.88 | J36: =F36+H36 -> 511890.88 | N36: 368190 | O36: =$O$1 -> 1.149 | P36: =SUM(O36*N36) -> 423050.31 | Q36: =SUM(N36*D36) -> 368190 | S36: =SUM(N36*0.21) -> 77319.9 | T36: =$T$1 -> 1.149 | U36: =SUM(T36*S36) -> 88840.565 | V36: =SUM(S36*D36) -> 77319.9
E37: =SUM(P37) -> 0 | F37: =D37*E37 -> 0 | G37: =SUM(U37) -> 0 | H37: =D37*G37 -> 0 | I37: =E37+G37 -> 0 | J37: =F37+H37 -> 0 | O37: =$O$1 -> 1.149 | P37: =SUM(O37*N37) -> 0 | Q37: =SUM(N37*D37) -> 0 | T37: =$T$1 -> 1.149 | U37: =SUM(T37*S37) -> 0 | V37: =SUM(S37*D37) -> 0
B38: 3VA125-1AA32-0AA0 Jistič | C38: Ks | D38: 2 | E38: =SUM(P38) -> 0 | F38: =D38*E38 -> 0 | G38: =SUM(U38) -> 0 | H38: =D38*G38 -> 0 | I38: =E38+G38 -> 0 | J38: =F38+H38 -> 0 | O38: =$O$1 -> 1.149 | P38: =SUM(O38*N38) -> 0 | Q38: =SUM(N38*D38) -> 0 | T38: =$T$1 -> 1.149 | U38: =SUM(T38*S38) -> 0 | V38: =SUM(S38*D38) -> 0
B39: 3VA9988-0BL33 Vypínací cívka | C39: Ks | D39: 1 | E39: =SUM(P39) -> 0 | F39: =D39*E39 -> 0 | G39: =SUM(U39) -> 0 | H39: =D39*G39 -> 0 | I39: =E39+G39 -> 0 | J39: =F39+H39 -> 0 | O39: =$O$1 -> 1.149 | P39: =SUM(O39*N39) -> 0 | Q39: =SUM(N39*D39) -> 0 | T39: =$T$1 -> 1.149 | U39: =SUM(T39*S39) -> 0 | V39: =SUM(S39*D39) -> 0
B40: RCD510 Proudový chránič | C40: Ks | D40: 1 | E40: =SUM(P40) -> 0 | F40: =D40*E40 -> 0 | G40: =SUM(U40) -> 0 | H40: =D40*G40 -> 0 | I40: =E40+G40 -> 0 | J40: =F40+H40 -> 0 | O40: =$O$1 -> 1.149 | P40: =SUM(O40*N40) -> 0 | Q40: =SUM(N40*D40) -> 0 | T40: =$T$1 -> 1.149 | U40: =SUM(T40*S40) -> 0 | V40: =SUM(S40*D40) -> 0
...

Sheet SLP_R1
M1: 1.149 | Q1: 1.149
L2: Dodávka "A" | M2: Koeficient | N2: Dodávka "C" | P2: Montáž "A" | Q2: Koeficient | R2: Montáž "C"
C3: Příprava kabelových tras, montáž + dodávka
A4: No. | B4: Číslo položky | C4: Popis položky | D4: DPS | E4: REV1 příp./odp. | F4: MN. | G4: Počet | H4: jedn. cena | I4: celkem
A5: 1 | B5: 220 111761 | C5: Svorka uzemňovací (mont. vč. materiálu) | D5: 5 | F5: =D5 -> 5 | G5: ks | H5: =N5+R5 -> 64.2291 | I5: =H5*F5 -> 321.1455 | L5: 10.9 | M5: =$M$1 -> 1.149 | N5: =L5*M5 -> 12.5241 | P5: 45 | Q5: =Q$1 -> 1.149 | R5: =P5*Q5 -> 51.705
A6: 2 | B6: 220 111765 | C6: Změření zemního odporu | D6: 5 | F6: =D6 -> 5 | G6: ks | H6: =N6+R6 -> 172.35 | I6: =H6*F6 -> 861.75 | M6: =$M$1 -> 1.149 | N6: =L6*M6 -> 0 | P6: 150 | Q6: =Q$1 -> 1.149 | R6: =P6*Q6 -> 172.35
A7: 3 | B7: KEV.000.8940 | C7: CY 6 ZZ | D7: 245 | F7: =D7 -> 245 | G7: m | H7: =N7+R7 -> 18.9585 | I7: =H7*F7 -> 4644.8325 | L7: 16.5 | M7: =$M$1 -> 1.149 | N7: =L7*M7 -> 18.9585 | Q7: =Q$1 -> 1.149 | R7: =P7*Q7 -> 0
A8: 4 | B8: 220 270329 | C8: Vodič v trubkovodu CY 6 | D8: 245 | F8: =D8 -> 245 | G8: m | H8: =N8+R8 -> 20.682 | I8: =H8*F8 -> 5067.09 | L8: 18 | M8: =$M$1 -> 1.149 | N8: =L8*M8 -> 20.682 | Q8: =Q$1 -> 1.149 | R8: =P8*Q8 -> 0
A9: 5 | B9: 220 260021 | C9: Krabice KO 68 pod omítku vč. vysekání lůžka (mont. vč. materiálu) | D9: 124 | E9: 24 | F9: =D9+E9 -> 148 | G9: ks | H9: =N9+R9 -> 5.45775 | I9: =H9*F9 -> 807.747 | L9: 4.75 | M9: =$M$1 -> 1.149 | N9: =L9*M9 -> 5.45775 | Q9: =Q$1 -> 1.149 | R9: =P9*Q9 -> 0
A10: 6 | B10: 220 260024 | C10: Krabice KO 97 pod omítku vč. vysekání lůžka (mont. vč. materiálu) | D10: 62 | E10: 12 | F10: =D10+E10 -> 74 | G10: ks | H10: =N10+R10 -> 27.51855 | I10: =H10*F10 -> 2036.3727 | L10: 23.95 | M10: =$M$1 -> 1.149 | N10: =L10*M10 -> 27.51855 | Q10: =Q$1 -> 1.149 | R10: =P10*Q10 -> 0
A11: 7 | B11: 220 260027 | C11: Krabice KO 125 pod omítku vč. vysekání lůžka (mont. vč. materiálu) | D11: 8 | F11: =D11 -> 8 | G11: ks | H11: =N11+R11 -> 98.4693 | I11: =H11*F11 -> 787.7544 | L11: 85.7 | M11: =$M$1 -> 1.149 | N11: =L11*M11 -> 98.4693 | Q11: =Q$1 -> 1.149 | R11: =P11*Q11 -> 0
A12: 8 | B12: 220 260028 | C12: Krabice KT 250 pod omítku vč. vysekání lůžka (mont. vč. materiálu) | D12: 8 | F12: =D12 -> 8 | G12: ks | H12: =N12+R12 -> 303.5658 | I12: =H12*F12 -> 2428.5264 | L12: 264.2 | M12: =$M$1 -> 1.149 | N12: =L12*M12 -> 303.5658 | Q12: =Q$1 -> 1.149 | R12: =P12*Q12 -> 0
A13: 9 | B13: 220 260103 | C13: Krabice instalační IP66 (mont. vč. materiálu) | D13: 44 | F13: =D13 -> 44 | G13: ks | H13: =N13+R13 -> 100.67538 | I13: =H13*F13 -> 4429.7167 | L13: 42.62 | M13: =$M$1 -> 1.149 | N13: =L13*M13 -> 48.97038 | P13: 45 | Q13: =Q$1 -> 1.149 | R13: =P13*Q13 -> 51.705
A14: 10 | B14: 220 260106 | C14: Vyhledání vývodu, krabice | D14: 202 | E14: 36 | F14: =D14+E14 -> 238 | G14: ks | H14: =N14+R14 -> 10.341 | I14: =H14*F14 -> 2461.158 | M14: =$M$1 -> 1.149 | N14: =L14*M14 -> 0 | P14: 9 | Q14: =Q$1 -> 1.149 | R14: =P14*Q14 -> 10.341
A15: 11 | B15: 220 260111 | C15: Odvíčkování a zavíčkování krabice na závit | D15: 186 | E15: 36 | F15: =D15+E15 -> 222 | G15: ks | H15: =N15+R15 -> 4.596 | I15: =H15*F15 -> 1020.312 | M15: =$M$1 -> 1.149 | N15: =L15*M15 -> 0 | P15: 4 | Q15: =Q$1 -> 1.149 | R15: =P15*Q15 -> 4.596
A16: 12 | B16: 220 260113 | C16: Odvíčkování a zavíčkování krabice na 4 šrouby | D16: 8 | F16: =D16 -> 8 | G16: ks | H16: =N16+R16 -> 4.596 | I16: =H16*F16 -> 36.768 | M16: =$M$1 -> 1.149 | N16: =L16*M16 -> 0 | P16: 4 | Q16: =Q$1 -> 1.149 | R16: =P16*Q16 -> 4.596
A17: 13 | B17: 220 260552 | C17: Trubka plastová ohebná pod omítkou nebo v podlaze 23 mm (mont. vč. materiálu) | D17: 186 | E17: 265 | F17: =D17+E17 -> 451 | G17: m | H17: =N17+R17 -> 28.40328 | I17: =H17*F17 -> 12809.879 | L17: 5.72 | M17: =$M$1 -> 1.149 | N17: =L17*M17 -> 6.57228 | P17: 19 | Q17: =Q$1 -> 1.149 | R17: =P17*Q17 -> 21.831
A18: 15 | B18: 220 260554 | C18: Trubka plastová ohebná pod omítkou nebo v podlaze 36 mm (mont. vč. materiálu) | D18: 82 | F18: =D18 -> 82 | G18: m | H18: =N18+R18 -> 40.27245 | I18: =H18*F18 -> 3302.3409 | L18: 16.05 | M18: =$M$1 -> 1.149 | N18: =L18*M18 -> 18.44145 | P18: 19 | Q18: =Q$1 -> 1.149 | R18: =P18*Q18 -> 21.831
A19: 16 | B19: 220 260542 | C19: Trubka plastová pevná na povrchu 23 mm (mont. vč. materiálu) | D19: 122 | F19: =D19 -> 122 | G19: m | H19: =N19+R19 -> 39.1809 | I19: =H19*F19 -> 4780.0698 | L19: 15.1 | M19: =$M$1 -> 1.149 | N19: =L19*M19 -> 17.3499 | P19: 19 | Q19: =Q$1 -> 1.149 | R19: =P19*Q19 -> 21.831
A20: 18 | B20: 220 260544 | C20: Trubka plastová pevná na povrchu 36 mm (mont. vč. materiálu) | D20: 66 | F20: =D20 -> 66 | G20: m | H20: =N20+R20 -> 54.003 | I20: =H20*F20 -> 3564.198 | L20: 28 | M20: =$M$1 -> 1.149 | N20: =L20*M20 -> 32.172 | P20: 19 | Q20: =Q$1 -> 1.149 | R20: =P20*Q20 -> 21.831
A21: 19 | B21: KEV.050.0400 | C21: AY 2,5 B | D21: 268 | E21: 265 | F21: =D21+E21 -> 533 | G21: m | H21: =N21+R21 -> 4.0215 | I21: =H21*F21 -> 2143.4595 | L21: 3.5 | M21: =$M$1 -> 1.149 | N21: =L21*M21 -> 4.0215 | Q21: =Q$1 -> 1.149 | R21: =P21*Q21 -> 0
A22: 20 | B22: 220 261661 | C22: Značení trasy vedení | D22: 268 | E22: 265 | F22: =D22+E22 -> 533 | G22: m | H22: =N22+R22 -> 4.8258 | I22: =H22*F22 -> 2572.1514 | M22: =$M$1 -> 1.149 | N22: =L22*M22 -> 0 | P22: 4.2 | Q22: =Q$1 -> 1.149 | R22: =P22*Q22 -> 4.8258
A23: 21 | B23: 220 270301 | C23: Vodič v trubkovodu AY 2,5 | D23: 268 | E23: 265 | F23: =D23+E23 -> 533 | G23: m | H23: =N23+R23 -> 4.596 | I23: =H23*F23 -> 2449.668 | M23: =$M$1 -> 1.149 | N23: =L23*M23 -> 0 | P23: 4 | Q23: =Q$1 -> 1.149 | R23: =P23*Q23 -> 4.596
A24: 22 | B24: 220260722 | C24: Žlab MARS 62/50 mm (mont. vč. základního i instalačního materiálu) | D24: 42 | F24: =D24 -> 42 | G24: m | H24: =N24+R24 -> 367.68 | I24: =H24*F24 -> 15442.56 | L24: 180 | M24: =$M$1 -> 1.149 | N24: =L24*M24 -> 206.82 | P24: 140 | Q24: =Q$1 -> 1.149 | R24: =P24*Q24 -> 160.86
A25: 23 | B25: 220 260722 | C25: Žlab MARS 125/ 50 mm (mont. vč. základního i instalačního materiálu) | D25: 0 | F25: =D25 -> 0 | G25: m | H25: =N25+R25 -> 436.62 | I25: =H25*F25 -> 0 | L25: 220 | M25: =$M$1 -> 1.149 | N25: =L25*M25 -> 252.78 | P25: 160 | Q25: =Q$1 -> 1.149 | R25: =P25*Q25 -> 183.84
A26: 24 | B26: 220 260725 | C26: Žlab MARS 250/50 mm (mont. vč. základního i instalačního materiálu) | D26: 108 | F26: =D26 -> 108 | G26: m | H26: =N26+R26 -> 596.331 | I26: =H26*F26 -> 64403.748 | L26: 319 | M26: =$M$1 -> 1.149 | N26: =L26*M26 -> 366.531 | P26: 200 | Q26: =Q$1 -> 1.149 | R26: =P26*Q26 -> 229.8
A27: 25 | B27: 220 260924 | C27: Kabelový rošt šíře 40cm (mont. vč. základního i instalačního materiálu) | D27: 4 | F27: =D27 -> 4 | G27: m | H27: =N27+R27 -> 884.73 | I27: =H27*F27 -> 3538.92 | L27: 630 | M27: =$M$1 -> 1.149 | N27: =L27*M27 -> 723.87 | P27: 140 | Q27: =Q$1 -> 1.149 | R27: =P27*Q27 -> 160.86
A28: 26 | B28: 220 261101 | C28: Konstrukce ocelová do 5 kg na m (mont. vč. materiálu) | D28: 96 | F28: =D28 -> 96 | G28: ks | H28: =N28+R28 -> 51.705 | I28: =H28*F28 -> 4963.68 | L28: 45 | M28: =$M$1 -> 1.149 | N28: =L28*M28 -> 51.705 | Q28: =Q$1 -> 1.149 | R28: =P28*Q28 -> 0
A29: 27 | B29: 220 261102 | C29: Konstrukce ocelová do 10 kg na m (mont. vč. materiálu) | D29: 216 | F29: =D29 -> 216 | G29: ks | H29: =N29+R29 -> 74.685 | I29: =H29*F29 -> 16131.96 | L29: 65 | M29: =$M$1 -> 1.149 | N29: =L29*M29 -> 74.685 | Q29: =Q$1 -> 1.149 | R29: =P29*Q29 -> 0
A30: 28 | B30: 220 261653 | C30: Uchycení ocelové konstrukce beton | D30: 308 | F30: =D30 -> 308 | G30: ks | H30: =N30+R30 -> 74.685 | I30: =H30*F30 -> 23002.98 | M30: =$M$1 -> 1.149 | N30: =L30*M30 -> 0 | P30: 65 | Q30: =Q$1 -> 1.149 | R30: =P30*Q30 -> 74.685
A31: 29 | B31: 220 261641 | C31: Osazení hmoždinky 6 mm beton (mont. vč. materiálu) | D31: 78 | F31: =D31 -> 78 | G31: ks | H31: =N31+R31 -> 6.894 | I31: =H31*F31 -> 537.732 | M31: =$M$1 -> 1.149 | N31: =L31*M31 -> 0 | P31: 6 | Q31: =Q$1 -> 1.149 | R31: =P31*Q31 -> 6.894
A32: 30 | B32: 220 261642 | C32: Osazení hmoždinky 8 mm beton (mont. vč. materiálu) | D32: 1020 | F32: =D32 -> 1020 | G32: ks | H32: =N32+R32 -> 6.894 | I32: =H32*F32 -> 7031.88 | M32: =$M$1 -> 1.149 | N32: =L32*M32 -> 0 | P32: 6 | Q32: =Q$1 -> 1.149 | R32: =P32*Q32 -> 6.894
A33: 31 | B33: 220 261643 | C33: Osazení hmoždinky 10 mm beton (mont. vč. materiálu) | D33: 84 | F33: =D33 -> 84 | G33: ks | H33: =N33+R33 -> 8.043 | I33: =H33*F33 -> 675.612 | M33: =$M$1 -> 1.149 | N33: =L33*M33 -> 0 | P33: 7 | Q33: =Q$1 -> 1.149 | R33: =P33*Q33 -> 8.043
A34: 32 | B34: 220 261644 | C34: Osazení hmoždinky 12 mm beton (mont. vč. materiálu) | D34: 224 | F34: =D34 -> 224 | G34: ks | H34: =N34+R34 -> 8.043 | I34: =H34*F34 -> 1801.632 | M34: =$M$1 -> 1.149 | N34: =L34*M34 -> 0 | P34: 7 | Q34: =Q$1 -> 1.149 | R34: =P34*Q34 -> 8.043
A35: 33 | B35: 220 730032 | C35: Vyzvednutí stožáru na plochou střechu | D35: 1 | F35: =D35 -> 1 | G35: ks | H35: =N35+R35 -> 172.35 | I35: =H35*F35 -> 172.35 | M35: =$M$1 -> 1.149 | N35: =L35*M35 -> 0 | P35: 150 | Q35: =Q$1 -> 1.149 | R35: =P35*Q35 -> 172.35
A36: 34 | B36: 220 730033 | C36: Vyzvednutí soupravy beton. bloků AT | D36: 1 | F36: =D36 -> 1 | G36: ks | H36: =N36+R36 -> 344.7 | I36: =H36*F36 -> 344.7 | M36: =$M$1 -> 1.149 | N36: =L36*M36 -> 0 | P36: 300 | Q36: =Q$1 -> 1.149 | R36: =P36*Q36 -> 344.7
A37: 35 | B37: 220 730051 | C37: Stožár AT 1 do kotevní konstrukce (mont. vč. materiálu) | D37: 1 | F37: =D37 -> 1 | G37: ks | H37: =N37+R37 -> 172.35 | I37: =H37*F37 -> 172.35 | M37: =$M$1 -> 1.149 | N37: =L37*M37 -> 0 | P37: 150 | Q37: =Q$1 -> 1.149 | R37: =P37*Q37 -> 172.35
A38: 36 | B38: 220 730075 | C38: Kotvení AT 3 do zdi-beton rovná střecha (mont. vč. materiálu) | D38: 1 | F38: =D38 -> 1 | G38: ks | H38: =N38+R38 -> 172.35 | I38: =H38*F38 -> 172.35 | M38: =$M$1 -> 1.149 | N38: =L38*M38 -> 0 | P38: 150 | Q38: =Q$1 -> 1.149 | R38: =P38*Q38 -> 172.35
A39: 37 | B39: 210 020922 | C39: Protipož.ucpávka průch.stěnou t= do 30 cm (mont. vč. materiálu) | D39: 0.2 | F39: =D39 -> 0.2 | G39: m2 | H39: =N39+R39 -> 0 | I39: =H39*F39 -> 0 | M39: =$M$1 -> 1.149 | N39: =L39*M39 -> 0 | Q39: =Q$1 -> 1.149 | R39: =P39*Q39 -> 0
A40: 38 | C40: Koordinace zařízení v zárubních či dveřích | D40: 2 | F40: =D40 -> 2 | G40: hod | H40: =N40+R40 -> 344.7 | I40: =H40*F40 -> 689.4 | M40: =$M$1 -> 1.149 | N40: =L40*M40 -> 0 | P40: 300 | Q40: =Q$1 -> 1.149 | R40: =P40*Q40 -> 344.7
...

Sheet NN + VO
B1: Název | C1: Mj | D1: Počet | E1: Materiál | F1: Materiál celkem | G1: Montáž | H1: Montáž celkem | I1: Cena | J1: Cena celkem | O1: =REK!F5 -> 1.149 | T1: =SUM(O1) -> 1.149
N2: Dodávka "A" | O2: Koeficient | P2: Dodávka "C" | S2: Montáž "A" | T2: Koeficient | U2: Montáž "C"
B3: Elektromontáže
B5: D.1.13 - SO 44 Přípojka NN, Areálové rozvody NN a VO
B7: Rozváděč (pilíř) nabíjecí stanice
B8: Skříň PR2S, Elpalst Rokycany | C8: ks | D8: 1 | E8: =SUM(P8) -> 9768.212 | F8: =D8*E8 -> 9768.212 | G8: =SUM(U8) -> 3907.2848 | H8: =D8*G8 -> 3907.2848 | I8: =E8+G8 -> 13675.497 | J8: =F8+H8 -> 13675.497 | N8: 8501.49 | O8: =$O$1 -> 1.149 | P8: =SUM(O8*N8) -> 9768.212 | Q8: =SUM(N8*D8) -> 8501.49 | S8: =SUM(N8*0.4) -> 3400.596 | T8: =$T$1 -> 1.149 | U8: =SUM(T8*S8) -> 3907.2848 | V8: =SUM(S8*D8) -> 3400.596
B9: Zámek čtyřhran | C9: ks | D9: 2 | E9: =SUM(P9) -> 103.65129 | F9: =D9*E9 -> 207.30258 | G9: =SUM(U9) -> 287.25 | H9: =D9*G9 -> 574.5 | I9: =E9+G9 -> 390.90129 | J9: =F9+H9 -> 781.80258 | L9: =SUM(J9) -> 781.80258 | N9: 90.21 | O9: =$O$1 -> 1.149 | P9: =SUM(O9*N9) -> 103.65129 | Q9: =SUM(N9*D9) -> 180.42 | S9: 250 | T9: =$T$1 -> 1.149 | U9: =SUM(T9*S9) -> 287.25 | V9: =SUM(S9*D9) -> 500
B10: Montážní panel 2M | C10: ks | D10: 1 | E10: =SUM(P10) -> 1003.6975 | F10: =D10*E10 -> 1003.6975 | G10: =SUM(U10) -> 517.05 | H10: =D10*G10 -> 517.05 | I10: =E10+G10 -> 1520.7475 | J10: =F10+H10 -> 1520.7475 | N10: 873.54 | O10: =$O$1 -> 1.149 | P10: =SUM(O10*N10) -> 1003.6975 | Q10: =SUM(N10*D10) -> 873.54 | S10: 450 | T10: =$T$1 -> 1.149 | U10: =SUM(T10*S10) -> 517.05 | V10: =SUM(S10*D10) -> 450
B11: ŘADOVÁ SVORKOVNICE | Q11: =SUM(N11*D11) -> 0 | V11: =SUM(S11*D11) -> 0
B12: RSA25 | C12: ks | D12: 5 | E12: =SUM(P12) -> 41.529456 | F12: =D12*E12 -> 207.64728 | G12: =SUM(U12) -> 22.98 | H12: =D12*G12 -> 114.9 | I12: =E12+G12 -> 64.509456 | J12: =F12+H12 -> 322.54728 | N12: 36.144 | O12: =$O$1 -> 1.149 | P12: =SUM(O12*N12) -> 41.529456 | Q12: =SUM(N12*D12) -> 180.72 | S12: 20 | T12: =$T$1 -> 1.149 | U12: =SUM(T12*S12) -> 22.98 | V12: =SUM(S12*D12) -> 100
B13: Rozváděč (pilíř) nabíjecí stanice - celkem | F13: =SUM(F8:F12) -> 11186.859 | H13: =SUM(H8:H12) -> 5113.7348 | J13: =SUM(J8:J12) -> 16300.594 | Q13: =SUM(N13*D13) -> 0 | V13: =SUM(S13*D13) -> 0
Q14: =SUM(N14*D14) -> 0 | V14: =SUM(S14*D14) -> 0
B15: Svítidla | Q15: =SUM(N15*D15) -> 0 | V15: =SUM(S15*D15) -> 0
B16: CHA1 (H1) - THOME Lighting s.r.o. MOD0007_280W_840_60° MODY, 42000lm,280W,IP66,4K,60°, | C16: ks | D16: 5 | E16: =SUM(P16) -> 0 | F16: =D16*E16 -> 0 | G16: =SUM(U16) -> 402.15 | H16: =D16*G16 -> 2010.75 | I16: =E16+G16 -> 402.15 | J16: =F16+H16 -> 2010.75 | O16: =$O$1 -> 1.149 | P16: =SUM(O16*N16) -> 0 | Q16: =SUM(N16*D16) -> 0 | S16: 350 | T16: =$T$1 -> 1.149 | U16: =SUM(T16*S16) -> 402.15 | V16: =SUM(S16*D16) -> 1750
B17: V1 - THOME Lighting s.r.o. TIT2010_69 TITANIA 2G,7800lm, 57W, IP65, 4K, ASTRODIM+CLO | C17: ks | D17: 1 | E17: =SUM(P17) -> 0 | F17: =D17*E17 -> 0 | G17: =SUM(U17) -> 402.15 | H17: =D17*G17 -> 402.15 | I17: =E17+G17 -> 402.15 | J17: =F17+H17 -> 402.15 | O17: =$O$1 -> 1.149 | P17: =SUM(O17*N17) -> 0 | Q17: =SUM(N17*D17) -> 0 | S17: 350 | T17: =$T$1 -> 1.149 | U17: =SUM(T17*S17) -> 402.15 | V17: =SUM(S17*D17) -> 350
B18: SL002 Poplatek za recyklaci svítidla | C18: ks | D18: 6 | E18: =SUM(P18) -> 0 | F18: =D18*E18 -> 0 | G18: =SUM(U18) -> 0 | H18: =D18*G18 -> 0 | I18: =E18+G18 -> 0 | J18: =F18+H18 -> 0 | O18: =$O$1 -> 1.149 | P18: =SUM(O18*N18) -> 0 | Q18: =SUM(N18*D18) -> 0 | T18: =$T$1 -> 1.149 | U18: =SUM(T18*S18) -> 0 | V18: =SUM(S18*D18) -> 0
B19: Svítidla - celkem | F19: =SUM(F16:F18) -> 0 | H19: =SUM(H16:H18) -> 2412.9 | J19: =SUM(J16:J18) -> 2412.9 | Q19: =SUM(N19*D19) -> 0 | V19: =SUM(S19*D19) -> 0
Q20: =SUM(N20*D20) -> 0 | V20: =SUM(S20*D20) -> 0
B21: Sloupy VO | Q21: =SUM(N21*D21) -> 0 | V21: =SUM(S21*D21) -> 0
B22: OSVĚTLOVACÍ STOŽÁR BEZPATICOVÝ | Q22: =SUM(N22*D22) -> 0 | V22: =SUM(S22*D22) -> 0
B23: METALIZOVANÝ | K23: nově | M23: původní | Q23: =SUM(N23*D23) -> 0 | V23: =SUM(S23*D23) -> 0
B24: JBUD14 DD, jmenovitá výška nad zemí 14m. stožár silniční, bezpaticový, dvoudílný | C24: ks | D24: 2 | E24: =SUM(P24) -> 18457.778 | F24: =D24*E24 -> 36915.556 | G24: =SUM(U24) -> 3964.05 | H24: =D24*G24 -> 7928.1 | I24: =E24+G24 -> 22421.828 | J24: =F24+H24 -> 44843.656 | K24: =SUM(L24)*D24 -> 28826 | L24: 14413 | M24: =SUM(N24*D24) -> 32128.421 | N24: 16064.211 | O24: =$O$1 -> 1.149 | P24: =SUM(O24*N24) -> 18457.778 | Q24: =SUM(N24*D24) -> 32128.421 | S24: 3450 | T24: =$T$1 -> 1.149 | U24: =SUM(T24*S24) -> 3964.05 | V24: =SUM(S24*D24) -> 6900
B25: JBUD9 9m, jmenovitá výška nad zemí 9m. stožár silniční, bezpaticový | C25: ks | D25: 1 | E25: =SUM(P25) -> 9853.5821 | F25: =D25*E25 -> 9853.5821 | G25: =SUM(U25) -> 3332.1 | H25: =D25*G25 -> 3332.1 | I25: =E25+G25 -> 13185.682 | J25: =F25+H25 -> 13185.682 | K25: =SUM(L25)*D25 -> 7263 | L25: 7263 | M25: =SUM(N25*D25) -> 8575.7895 | N25: 8575.7895 | O25: =$O$1 -> 1.149 | P25: =SUM(O25*N25) -> 9853.5821 | Q25: =SUM(N25*D25) -> 8575.7895 | S25: 2900 | T25: =$T$1 -> 1.149 | U25: =SUM(T25*S25) -> 3332.1 | V25: =SUM(S25*D25) -> 2900
B26: VÝLOŽNÍK | K26: =SUM(L26)*D26 -> 0 | M26: =SUM(N26*D26) -> 0 | Q26: =SUM(N26*D26) -> 0 | V26: =SUM(S26*D26) -> 0
B27: Držák reflektorů, typ TR2-1500-PL (AMAKO) pro dva reflektory | C27: ks | D27: 1 | E27: =SUM(P27) -> 3909.0189 | F27: =D27*E27 -> 3909.0189 | G27: =SUM(U27) -> 689.4 | H27: =D27*G27 -> 689.4 | I27: =E27+G27 -> 4598.4189 | J27: =F27+H27 -> 4598.4189 | K27: =SUM(L27)*D27 -> 2741 | L27: 2741 | M27: =SUM(N27*D27) -> 3402.1053 | N27: 3402.1053 | O27: =$O$1 -> 1.149 | P27: =SUM(O27*N27) -> 3909.0189 | Q27: =SUM(N27*D27) -> 3402.1053 | S27: 600 | T27: =$T$1 -> 1.149 | U27: =SUM(T27*S27) -> 689.4 | V27: =SUM(S27*D27) -> 600
B28: Držák reflektorů, typ TR3-1500-PL (AMAKO) pro tři reflektory | C28: ks | D28: 1 | E28: =SUM(P28) -> 0 | F28: =D28*E28 -> 0 | G28: =SUM(U28) -> 689.4 | H28: =D28*G28 -> 689.4 | I28: =E28+G28 -> 689.4 | J28: =F28+H28 -> 689.4 | K28: =SUM(L28)*D28 -> 3995 | L28: 3995 | M28: =SUM(N28*D28) -> 0 | O28: =$O$1 -> 1.149 | P28: =SUM(O28*N28) -> 0 | Q28: =SUM(N28*D28) -> 0 | S28: 600 | T28: =$T$1 -> 1.149 | U28: =SUM(T28*S28) -> 689.4 | V28: =SUM(S28*D28) -> 600
B29: UD 1/89-1000, výložník rovný pro stožáry typu JB, JBUD, LPH, J | C29: ks | D29: 1 | E29: =SUM(P29) -> 1196.1695 | F29: =D29*E29 -> 1196.1695 | G29: =SUM(U29) -> 689.4 | H29: =D29*G29 -> 689.4 | I29: =E29+G29 -> 1885.5695 | J29: =F29+H29 -> 1885.5695 | K29: =SUM(L29)*D29 -> 934 | L29: 934 | M29: =SUM(N29*D29) -> 1041.0526 | N29: 1041.0526 | O29: =$O$1 -> 1.149 | P29: =SUM(O29*N29) -> 1196.1695 | Q29: =SUM(N29*D29) -> 1041.0526 | S29: 600 | T29: =$T$1 -> 1.149 | U29: =SUM(T29*S29) -> 689.4 | V29: =SUM(S29*D29) -> 600
B30: STOŽÁROVÁ VÝZBROJ | K30: =SUM(L30)*D30 -> 0 | M30: =SUM(N30*D30) -> 0 | Q30: =SUM(N30*D30) -> 0 | V30: =SUM(S30*D30) -> 0
B31: SV 6.16.4 | C31: ks | D31: 1 | E31: =SUM(P31) -> 404.87132 | F31: =D31*E31 -> 404.87132 | G31: =SUM(U31) -> 631.95 | H31: =D31*G31 -> 631.95 | I31: =E31+G31 -> 1036.8213 | J31: =F31+H31 -> 1036.8213 | K31: =SUM(L31)*D31 -> 352 | L31: 352 | M31: =SUM(N31*D31) -> 352.36842 | N31: 352.36842 | O31: =$O$1 -> 1.149 | P31: =SUM(O31*N31) -> 404.87132 | Q31: =SUM(N31*D31) -> 352.36842 | S31: 550 | T31: =$T$1 -> 1.149 | U31: =SUM(T31*S31) -> 631.95 | V31: =SUM(S31*D31) -> 550
B32: SV 6.16.4/2 | C32: ks | D32: 1 | E32: =SUM(P32) -> 444.92908 | F32: =D32*E32 -> 444.92908 | G32: =SUM(U32) -> 631.95 | H32: =D32*G32 -> 631.95 | I32: =E32+G32 -> 1076.8791 | J32: =F32+H32 -> 1076.8791 | K32: =SUM(L32)*D32 -> 384 | L32: 384 | M32: =SUM(N32*D32) -> 387.23158 | N32: 387.23158 | O32: =$O$1 -> 1.149 | P32: =SUM(O32*N32) -> 444.92908 | Q32: =SUM(N32*D32) -> 387.23158 | S32: 550 | T32: =$T$1 -> 1.149 | U32: =SUM(T32*S32) -> 631.95 | V32: =SUM(S32*D32) -> 550
B33: SV 6.16.4/3 | C33: ks | D33: 1 | E33: =SUM(P33) -> 459.6 | F33: =D33*E33 -> 459.6 | G33: =SUM(U33) -> 746.85 | H33: =D33*G33 -> 746.85 | I33: =E33+G33 -> 1206.45 | J33: =F33+H33 -> 1206.45 | N33: 400 | O33: =$O$1 -> 1.149 | P33: =SUM(O33*N33) -> 459.6 | Q33: =SUM(N33*D33) -> 400 | S33: 650 | T33: =$T$1 -> 1.149 | U33: =SUM(T33*S33) -> 746.85 | V33: =SUM(S33*D33) -> 650
B34: Sloupy VO - celkem | F34: =SUM(F22:F33) -> 53183.727 | H34: =SUM(H22:H33) -> 15339.15 | J34: =SUM(J22:J33) -> 68522.877 | K34: =SUM(K24:K33) -> 44495 | M34: =SUM(M24:M33) -> 45886.968 | Q34: =SUM(N34*D34) -> 0 | V34: =SUM(S34*D34) -> 0
Q35: =SUM(N35*D35) -> 0 | V35: =SUM(S35*D35) -> 0
B36: Kabely | Q36: =SUM(N36*D36) -> 0 | V36: =SUM(S36*D36) -> 0
B37: KABEL SILOVÝ,IZOLACE PVC,1kV | Q37: =SUM(N37*D37) -> 0 | V37: =SUM(S37*D37) -> 0
B38: AYKY-J 3x120+70 | C38: m | D38: 350 | E38: =SUM(P38) -> 204.36477 | F38: =D38*E38 -> 71527.669 | G38: =SUM(U38) -> 51.705 | H38: =D38*G38 -> 18096.75 | I38: =E38+G38 -> 256.06977 | J38: =F38+H38 -> 89624.419 | N38: 177.86316 | O38: =$O$1 -> 1.149 | P38: =SUM(O38*N38) -> 204.36477 | Q38: =SUM(N38*D38) -> 62252.105 | S38: 45 | T38: =$T$1 -> 1.149 | U38: =SUM(T38*S38) -> 51.705 | V38: =SUM(S38*D38) -> 15750
B39: KABEL SILOVÝ,IZOLACE PVC | Q39: =SUM(N39*D39) -> 0 | V39: =SUM(S39*D39) -> 0
B40: CYKY-O 5x1.5 | C40: m | D40: 140 | E40: =SUM(P40) -> 22.592968 | F40: =D40*E40 -> 3163.0156 | G40: =SUM(U40) -> 25.278 | H40: =D40*G40 -> 3538.92 | I40: =E40+G40 -> 47.870968 | J40: =F40+H40 -> 6701.9356 | N40: 19.663158 | O40: =$O$1 -> 1.149 | P40: =SUM(O40*N40) -> 22.592968 | Q40: =SUM(N40*D40) -> 2752.8421 | S40: 22 | T40: =$T$1 -> 1.149 | U40: =SUM(T40*S40) -> 25.278 | V40: =SUM(S40*D40) -> 3080
B41: CYKY-O 4x1.5 | C41: m | D41: 175 | E41: =SUM(P41) -> 19.085495 | F41: =D41*E41 -> 3339.9616 | G41: =SUM(U41) -> 25.278 | H41: =D41*G41 -> 4423.65 | I41: =E41+G41 -> 44.363495 | J41: =F41+H41 -> 7763.6116 | N41: 16.610526 | O41: =$O$1 -> 1.149 | P41: =SUM(O41*N41) -> 19.085495 | Q41: =SUM(N41*D41) -> 2906.8421 | S41: 22 | T41: =$T$1 -> 1.149 | U41: =SUM(T41*S41) -> 25.278 | V41: =SUM(S41*D41) -> 3850
B42: KABEL SILOVÝ,IZOLACE PVC | Q42: =SUM(N42*D42) -> 0 | V42: =SUM(S42*D42) -> 0
...

Sheet Přípojka VN + TS
B1: Název | C1: Mj | D1: Počet | E1: Materiál | F1: Materiál celkem | G1: Montáž | H1: Montáž celkem | I1: Cena | J1: Cena celkem | M1: 1.19 | R1: 1.24
B2: Dodávky | L2: Dodávka "A" | M2: Koeficient | N2: Dodávka "C" | Q2: Montáž "A" | R2: Koeficient | S2: Montáž "C"
B4: Trafostanice
B5: Trafostanice, specifikace dle výkresu č. D.1.14.15.03 | C5: ks | D5: 1 | E5: =SUM(N5) -> 0 | F5: =D5*E5 -> 0 | G5: =SUM(S5) -> 0 | H5: =D5*G5 -> 0 | I5: =E5+G5 -> 0 | J5: =F5+H5 -> 0 | M5: =$M$1 -> 1.19 | N5: =SUM(M5*L5) -> 0 | R5: =$R$1 -> 1.24 | S5: =SUM(R5*Q5) -> 0
B6: Výstražné a informační tabulky | C6: sada | D6: 1 | E6: =SUM(N6) -> 0 | F6: =D6*E6 -> 0 | G6: =SUM(S6) -> 0 | H6: =D6*G6 -> 0 | I6: =E6+G6 -> 0 | J6: =F6+H6 -> 0 | M6: =$M$1 -> 1.19 | N6: =SUM(M6*L6) -> 0 | R6: =$R$1 -> 1.24 | S6: =SUM(R6*Q6) -> 0
B7: Ochranné pracovní pomůcky | C7: sada | D7: 1 | E7: =SUM(N7) -> 0 | F7: =D7*E7 -> 0 | G7: =SUM(S7) -> 0 | H7: =D7*G7 -> 0 | I7: =E7+G7 -> 0 | J7: =F7+H7 -> 0 | M7: =$M$1 -> 1.19 | N7: =SUM(M7*L7) -> 0 | R7: =$R$1 -> 1.24 | S7: =SUM(R7*Q7) -> 0
B8: Trafostanice - celkem | F8: =SUM(F5:F7) -> 0 | H8: =SUM(H5:H7) -> 0 | J8: =SUM(J5:J7) -> 0
B10: Dodávky - celkem | F10: =SUM(F3,F5:F7,F9:F9) -> 0 | H10: =SUM(H3,H5:H7,H9:H9) -> 0 | J10: =SUM(J3,J5:J7,J9:J9) -> 0
B12: Elektromontáže
B14: D.1.14 - SO45 Přípojka VN, D.1.15 - SO 46 Trafostanice
B16: Přípojka VN
B17: KABEL SILOVÝ,IZOLACE PE,35kV
B18: 35-AXEKVCEY 1x120/16 - Přípojka VN | C18: m | D18: 420 | E18: =SUM(N18) -> 0 | F18: =D18*E18 -> 0 | G18: =SUM(S18) -> 0 | H18: =D18*G18 -> 0 | I18: =E18+G18 -> 0 | J18: =F18+H18 -> 0 | M18: =$M$1 -> 1.19 | N18: =SUM(M18*L18) -> 0 | R18: =$R$1 -> 1.24 | S18: =SUM(R18*Q18) -> 0
B19: Svazkování 1-žilových vodičů ve výkopu, do 3-úhelníku | C19: m | D19: 130 | E19: =SUM(N19) -> 0 | F19: =D19*E19 -> 0 | G19: =SUM(S19) -> 0 | H19: =D19*G19 -> 0 | I19: =E19+G19 -> 0 | J19: =F19+H19 -> 0 | M19: =$M$1 -> 1.19 | N19: =SUM(M19*L19) -> 0 | R19: =$R$1 -> 1.24 | S19: =SUM(R19*Q19) -> 0
B20: Příplatek za protahování kabelů do chrániček - VN | C20: m | D20: 15 | E20: =SUM(N20) -> 0 | F20: =D20*E20 -> 0 | G20: =SUM(S20) -> 0 | H20: =D20*G20 -> 0 | I20: =E20+G20 -> 0 | J20: =F20+H20 -> 0 | M20: =$M$1 -> 1.19 | N20: =SUM(M20*L20) -> 0 | R20: =$R$1 -> 1.24 | S20: =SUM(R20*Q20) -> 0
B21: FXKVS 200/6M BK 450N/5cm, -25až60°C, PE-HD, včetně spojky, pevná, černa, 6m | C21: m | D21: 18 | E21: =SUM(N21) -> 0 | F21: =D21*E21 -> 0 | G21: =SUM(S21) -> 0 | H21: =D21*G21 -> 0 | I21: =E21+G21 -> 0 | J21: =F21+H21 -> 0 | M21: =$M$1 -> 1.19 | N21: =SUM(M21*L21) -> 0 | R21: =$R$1 -> 1.24 | S21: =SUM(R21*Q21) -> 0
B22: T- ADAPTÉR, SADA 3ks
B23: RSES-6452 - izolovaný T-adaptér pro 35kV kabel | C23: ks | D23: 1 | E23: =SUM(N23) -> 0 | F23: =D23*E23 -> 0 | G23: =SUM(S23) -> 0 | H23: =D23*G23 -> 0 | I23: =E23+G23 -> 0 | J23: =F23+H23 -> 0 | M23: =$M$1 -> 1.19 | N23: =SUM(M23*L23) -> 0 | R23: =$R$1 -> 1.24 | S23: =SUM(R23*Q23) -> 0
B24: KONCOVKA VENKOVNÍ PRO JEDNOŽIL
B25: JEDNOPLÁŠŤ.KAB. 35kV S PLAST.
B26: IZOLACÍ,SADA3ks
B27: POLT-42D/1XO-ML-2-13 | C27: ks | D27: 1 | E27: =SUM(N27) -> 0 | F27: =D27*E27 -> 0 | G27: =SUM(S27) -> 0 | H27: =D27*G27 -> 0 | I27: =E27+G27 -> 0 | J27: =F27+H27 -> 0 | M27: =$M$1 -> 1.19 | N27: =SUM(M27*L27) -> 0 | R27: =$R$1 -> 1.24 | S27: =SUM(R27*Q27) -> 0
B28: UKONČENÍ VN KABELŮ DO
B29: 1x120 mm2 | C29: ks | D29: 6 | E29: =SUM(N29) -> 0 | F29: =D29*E29 -> 0 | G29: =SUM(S29) -> 0 | H29: =D29*G29 -> 0 | I29: =E29+G29 -> 0 | J29: =F29+H29 -> 0 | M29: =$M$1 -> 1.19 | N29: =SUM(M29*L29) -> 0 | R29: =$R$1 -> 1.24 | S29: =SUM(R29*Q29) -> 0
B30: Magnetický označník kabelu MARKER | C30: ks | D30: 10 | E30: =SUM(N30) -> 0 | F30: =D30*E30 -> 0 | G30: =SUM(S30) -> 0 | H30: =D30*G30 -> 0 | I30: =E30+G30 -> 0 | J30: =F30+H30 -> 0 | M30: =$M$1 -> 1.19 | N30: =SUM(M30*L30) -> 0 | R30: =$R$1 -> 1.24 | S30: =SUM(R30*Q30) -> 0
B31: Utěsnění prostupu do budovy, těsnící průchodky RDSS100 | C31: ks | D31: 3 | E31: =SUM(N31) -> 0 | F31: =D31*E31 -> 0 | G31: =SUM(S31) -> 0 | H31: =D31*G31 -> 0 | I31: =E31+G31 -> 0 | J31: =F31+H31 -> 0 | M31: =$M$1 -> 1.19 | N31: =SUM(M31*L31) -> 0 | R31: =$R$1 -> 1.24 | S31: =SUM(R31*Q31) -> 0
B32: HODINOVE ZUCTOVACI SAZBY
B33: Nafázování VN kabelu | C33: sada | D33: 1 | E33: =SUM(N33) -> 0 | F33: =D33*E33 -> 0 | G33: =SUM(S33) -> 0 | H33: =D33*G33 -> 0 | I33: =E33+G33 -> 0 | J33: =F33+H33 -> 0 | M33: =$M$1 -> 1.19 | N33: =SUM(M33*L33) -> 0 | R33: =$R$1 -> 1.24 | S33: =SUM(R33*Q33) -> 0
B34: Příprava ke komplexní zkoušce | C34: hod | D34: 6 | E34: =SUM(N34) -> 0 | F34: =D34*E34 -> 0 | G34: =SUM(S34) -> 0 | H34: =D34*G34 -> 0 | I34: =E34+G34 -> 0 | J34: =F34+H34 -> 0 | M34: =$M$1 -> 1.19 | N34: =SUM(M34*L34) -> 0 | R34: =$R$1 -> 1.24 | S34: =SUM(R34*Q34) -> 0
B35: Zkušebni provoz | C35: hod | D35: 6 | E35: =SUM(N35) -> 0 | F35: =D35*E35 -> 0 | G35: =SUM(S35) -> 0 | H35: =D35*G35 -> 0 | I35: =E35+G35 -> 0 | J35: =F35+H35 -> 0 | M35: =$M$1 -> 1.19 | N35: =SUM(M35*L35) -> 0 | R35: =$R$1 -> 1.24 | S35: =SUM(R35*Q35) -> 0
B36: Zabezpečení pracoviště | C36: hod | D36: 12 | E36: =SUM(N36) -> 0 | F36: =D36*E36 -> 0 | G36: =SUM(S36) -> 0 | H36: =D36*G36 -> 0 | I36: =E36+G36 -> 0 | J36: =F36+H36 -> 0 | M36: =$M$1 -> 1.19 | N36: =SUM(M36*L36) -> 0 | R36: =$R$1 -> 1.24 | S36: =SUM(R36*Q36) -> 0
B37: Vysokonapěťové zkoušky | C37: ks | D37: 6 | E37: =SUM(N37) -> 0 | F37: =D37*E37 -> 0 | G37: =SUM(S37) -> 0 | H37: =D37*G37 -> 0 | I37: =E37+G37 -> 0 | J37: =F37+H37 -> 0 | M37: =$M$1 -> 1.19 | N37: =SUM(M37*L37) -> 0 | R37: =$R$1 -> 1.24 | S37: =SUM(R37*Q37) -> 0
B38: KOORDINACE POSTUPU PRACI
B39: S ostatnimi profesemi (ČEZ) | C39: hod | D39: 10 | E39: =SUM(N39) -> 0 | F39: =D39*E39 -> 0 | G39: =SUM(S39) -> 0 | H39: =D39*G39 -> 0 | I39: =E39+G39 -> 0 | J39: =F39+H39 -> 0 | M39: =$M$1 -> 1.19 | N39: =SUM(M39*L39) -> 0 | R39: =$R$1 -> 1.24 | S39: =SUM(R39*Q39) -> 0
B40: PROVEDENI REVIZNÍCH ZKOUŠEK
B41: DLE CSN 331500
B42: Revizní technik | C42: sada | D42: 1 | E42: =SUM(N42) -> 0 | F42: =D42*E42 -> 0 | G42: =SUM(S42) -> 0 | H42: =D42*G42 -> 0 | I42: =E42+G42 -> 0 | J42: =F42+H42 -> 0 | M42: =$M$1 -> 1.19 | N42: =SUM(M42*L42) -> 0 | R42: =$R$1 -> 1.24 | S42: =SUM(R42*Q42) -> 0
B43: Přípojka VN - celkem | F43: =SUM(F17:F42) -> 0 | H43: =SUM(H17:H42) -> 0 | J43: =SUM(J17:J42) -> 0
B45: Konstrukce na sloup
B46: Nosná konstrukce na příhradový sloup pro ochranu VN kabelů, výz výkresová dokumentace | C46: klp | D46: 1 | E46: =SUM(N46) -> 0 | F46: =D46*E46 -> 0 | G46: =SUM(S46) -> 0 | H46: =D46*G46 -> 0 | I46: =E46+G46 -> 0 | J46: =F46+H46 -> 0 | M46: =$M$1 -> 1.19 | N46: =SUM(M46*L46) -> 0 | R46: =$R$1 -> 1.24 | S46: =SUM(R46*Q46) -> 0
...

Sheet SLP_R0
K1: 1.19 | O1: =SUM(K1) -> 1.19
C2: Příprava kabelových tras, montáž + dodávka | J2: Dodávka "A" | K2: Koeficient | L2: Dodávka "C" | N2: Montáž "A" | O2: Koeficient | P2: Montáž "C"
A3: No. | B3: Číslo položky | C3: Popis položky | E3: Počet | F3: Jedn. cena | G3: Celkem | H3: Upravené množství
A4: 1 | B4: 220 111761 | C4: Svorka uzemňovací (mont. vč. materiálu) | D4: 5 | E4: ks | F4: =L4+P4 -> 66.521 | G4: =D4*F4 -> 332.605 | J4: 10.9 | K4: =$K$1 -> 1.19 | L4: =K4*J4 -> 12.971 | M4: =SUM(J4*D4) -> 54.5 | N4: 45 | O4: =$O$1 -> 1.19 | P4: =O4*N4 -> 53.55 | Q4: =SUM(N4*D4) -> 225
A5: 2 | B5: 220 111765 | C5: Změření zemního odporu | D5: 5 | E5: ks | F5: =L5+P5 -> 178.5 | G5: =D5*F5 -> 892.5 | K5: =$K$1 -> 1.19 | L5: =K5*J5 -> 0 | M5: =SUM(J5*D5) -> 0 | N5: 150 | O5: =$O$1 -> 1.19 | P5: =O5*N5 -> 178.5 | Q5: =SUM(N5*D5) -> 750
A6: 3 | B6: KEV.000.8940 | C6: CY 6 ZZ | D6: 245 | E6: m | F6: =L6+P6 -> 19.635 | G6: =D6*F6 -> 4810.575 | J6: 16.5 | K6: =$K$1 -> 1.19 | L6: =K6*J6 -> 19.635 | M6: =SUM(J6*D6) -> 4042.5 | O6: =$O$1 -> 1.19 | P6: =O6*N6 -> 0 | Q6: =SUM(N6*D6) -> 0
A7: 4 | B7: 220 270329 | C7: Vodič v trubkovodu CY 6 | D7: 245 | E7: m | F7: =L7+P7 -> 21.42 | G7: =D7*F7 -> 5247.9 | J7: 18 | K7: =$K$1 -> 1.19 | L7: =K7*J7 -> 21.42 | M7: =SUM(J7*D7) -> 4410 | O7: =$O$1 -> 1.19 | P7: =O7*N7 -> 0 | Q7: =SUM(N7*D7) -> 0
A8: 5 | B8: 220 260021 | C8: Krabice KO 68 pod omítku vč. vysekání lůžka (mont. vč. materiálu) | D8: 124 | E8: ks | F8: =L8+P8 -> 5.6525 | G8: =D8*F8 -> 700.91 | J8: 4.75 | K8: =$K$1 -> 1.19 | L8: =K8*J8 -> 5.6525 | M8: =SUM(J8*D8) -> 589 | O8: =$O$1 -> 1.19 | P8: =O8*N8 -> 0 | Q8: =SUM(N8*D8) -> 0
A9: 6 | B9: 220 260024 | C9: Krabice KO 97 pod omítku vč. vysekání lůžka (mont. vč. materiálu) | D9: 62 | E9: ks | F9: =L9+P9 -> 28.5005 | G9: =D9*F9 -> 1767.031 | J9: 23.95 | K9: =$K$1 -> 1.19 | L9: =K9*J9 -> 28.5005 | M9: =SUM(J9*D9) -> 1484.9 | O9: =$O$1 -> 1.19 | P9: =O9*N9 -> 0 | Q9: =SUM(N9*D9) -> 0
A10: 7 | B10: 220 260027 | C10: Krabice KO 125 pod omítku vč. vysekání lůžka (mont. vč. materiálu) | D10: 8 | E10: ks | F10: =L10+P10 -> 101.983 | G10: =D10*F10 -> 815.864 | J10: 85.7 | K10: =$K$1 -> 1.19 | L10: =K10*J10 -> 101.983 | M10: =SUM(J10*D10) -> 685.6 | O10: =$O$1 -> 1.19 | P10: =O10*N10 -> 0 | Q10: =SUM(N10*D10) -> 0
A11: 8 | B11: 220 260028 | C11: Krabice KT 250 pod omítku vč. vysekání lůžka (mont. vč. materiálu) | D11: 8 | E11: ks | F11: =L11+P11 -> 314.398 | G11: =D11*F11 -> 2515.184 | J11: 264.2 | K11: =$K$1 -> 1.19 | L11: =K11*J11 -> 314.398 | M11: =SUM(J11*D11) -> 2113.6 | O11: =$O$1 -> 1.19 | P11: =O11*N11 -> 0 | Q11: =SUM(N11*D11) -> 0
A12: 9 | B12: 220 260103 | C12: Krabice instalační IP66 (mont. vč. materiálu) | D12: 44 | E12: ks | F12: =L12+P12 -> 104.2678 | G12: =D12*F12 -> 4587.7832 | J12: 42.62 | K12: =$K$1 -> 1.19 | L12: =K12*J12 -> 50.7178 | M12: =SUM(J12*D12) -> 1875.28 | N12: 45 | O12: =$O$1 -> 1.19 | P12: =O12*N12 -> 53.55 | Q12: =SUM(N12*D12) -> 1980
A13: 10 | B13: 220 260106 | C13: Vyhledání vývodu, krabice | D13: 202 | E13: ks | F13: =L13+P13 -> 10.71 | G13: =D13*F13 -> 2163.42 | K13: =$K$1 -> 1.19 | L13: =K13*J13 -> 0 | M13: =SUM(J13*D13) -> 0 | N13: 9 | O13: =$O$1 -> 1.19 | P13: =O13*N13 -> 10.71 | Q13: =SUM(N13*D13) -> 1818
A14: 11 | B14: 220 260111 | C14: Odvíčkování a zavíčkování krabice na závit | D14: 186 | E14: ks | F14: =L14+P14 -> 4.76 | G14: =D14*F14 -> 885.36 | K14: =$K$1 -> 1.19 | L14: =K14*J14 -> 0 | M14: =SUM(J14*D14) -> 0 | N14: 4 | O14: =$O$1 -> 1.19 | P14: =O14*N14 -> 4.76 | Q14: =SUM(N14*D14) -> 744
A15: 12 | B15: 220 260113 | C15: Odvíčkování a zavíčkování krabice na 4 šrouby | D15: 8 | E15: ks | F15: =L15+P15 -> 4.76 | G15: =D15*F15 -> 38.08 | K15: =$K$1 -> 1.19 | L15: =K15*J15 -> 0 | M15: =SUM(J15*D15) -> 0 | N15: 4 | O15: =$O$1 -> 1.19 | P15: =O15*N15 -> 4.76 | Q15: =SUM(N15*D15) -> 32
A16: 13 | B16: 220 260552 | C16: Trubka plastová ohebná pod omítkou nebo v podlaze 23 mm (mont. vč. materiálu) | D16: 186 | E16: m | F16: =L16+P16 -> 29.4168 | G16: =D16*F16 -> 5471.5248 | J16: 5.72 | K16: =$K$1 -> 1.19 | L16: =K16*J16 -> 6.8068 | M16: =SUM(J16*D16) -> 1063.92 | N16: 19 | O16: =$O$1 -> 1.19 | P16: =O16*N16 -> 22.61 | Q16: =SUM(N16*D16) -> 3534
A17: 15 | B17: 220 260554 | C17: Trubka plastová ohebná pod omítkou nebo v podlaze 36 mm (mont. vč. materiálu) | D17: 82 | E17: m | F17: =L17+P17 -> 41.7095 | G17: =D17*F17 -> 3420.179 | J17: 16.05 | K17: =$K$1 -> 1.19 | L17: =K17*J17 -> 19.0995 | M17: =SUM(J17*D17) -> 1316.1 | N17: 19 | O17: =$O$1 -> 1.19 | P17: =O17*N17 -> 22.61 | Q17: =SUM(N17*D17) -> 1558
A18: 16 | B18: 220 260542 | C18: Trubka plastová pevná na povrchu 23 mm (mont. vč. materiálu) | D18: 122 | E18: m | F18: =L18+P18 -> 40.579 | G18: =D18*F18 -> 4950.638 | J18: 15.1 | K18: =$K$1 -> 1.19 | L18: =K18*J18 -> 17.969 | M18: =SUM(J18*D18) -> 1842.2 | N18: 19 | O18: =$O$1 -> 1.19 | P18: =O18*N18 -> 22.61 | Q18: =SUM(N18*D18) -> 2318
A19: 18 | B19: 220 260544 | C19: Trubka plastová pevná na povrchu 36 mm (mont. vč. materiálu) | D19: 66 | E19: m | F19: =L19+P19 -> 55.93 | G19: =D19*F19 -> 3691.38 | J19: 28 | K19: =$K$1 -> 1.19 | L19: =K19*J19 -> 33.32 | M19: =SUM(J19*D19) -> 1848 | N19: 19 | O19: =$O$1 -> 1.19 | P19: =O19*N19 -> 22.61 | Q19: =SUM(N19*D19) -> 1254
A20: 19 | B20: KEV.050.0400 | C20: AY 2,5 B | D20: 268 | E20: m | F20: =L20+P20 -> 4.165 | G20: =D20*F20 -> 1116.22 | J20: 3.5 | K20: =$K$1 -> 1.19 | L20: =K20*J20 -> 4.165 | M20: =SUM(J20*D20) -> 938 | O20: =$O$1 -> 1.19 | P20: =O20*N20 -> 0 | Q20: =SUM(N20*D20) -> 0
A21: 20 | B21: 220 261661 | C21: Značení trasy vedení | D21: 268 | E21: m | F21: =L21+P21 -> 4.998 | G21: =D21*F21 -> 1339.464 | K21: =$K$1 -> 1.19 | L21: =K21*J21 -> 0 | M21: =SUM(J21*D21) -> 0 | N21: 4.2 | O21: =$O$1 -> 1.19 | P21: =O21*N21 -> 4.998 | Q21: =SUM(N21*D21) -> 1125.6
A22: 21 | B22: 220 270301 | C22: Vodič v trubkovodu AY 2,5 | D22: 268 | E22: m | F22: =L22+P22 -> 4.76 | G22: =D22*F22 -> 1275.68 | K22: =$K$1 -> 1.19 | L22: =K22*J22 -> 0 | M22: =SUM(J22*D22) -> 0 | N22: 4 | O22: =$O$1 -> 1.19 | P22: =O22*N22 -> 4.76 | Q22: =SUM(N22*D22) -> 1072
A23: 22 | B23: 220260722 | C23: Žlab MARS 62/50 mm (mont. vč. základního i instalačního materiálu) | D23: 42 | E23: m | F23: =L23+P23 -> 380.8 | G23: =D23*F23 -> 15993.6 | J23: 180 | K23: =$K$1 -> 1.19 | L23: =K23*J23 -> 214.2 | M23: =SUM(J23*D23) -> 7560 | N23: 140 | O23: =$O$1 -> 1.19 | P23: =O23*N23 -> 166.6 | Q23: =SUM(N23*D23) -> 5880
A24: 23 | B24: 220 260722 | C24: Žlab MARS 125/ 50 mm (mont. vč. základního i instalačního materiálu) | D24: 0 | E24: m | F24: =L24+P24 -> 452.2 | G24: =D24*F24 -> 0 | J24: 220 | K24: =$K$1 -> 1.19 | L24: =K24*J24 -> 261.8 | M24: =SUM(J24*D24) -> 0 | N24: 160 | O24: =$O$1 -> 1.19 | P24: =O24*N24 -> 190.4 | Q24: =SUM(N24*D24) -> 0
A25: 24 | B25: 220 260725 | C25: Žlab MARS 250/50 mm (mont. vč. základního i instalačního materiálu) | D25: 108 | E25: m | F25: =L25+P25 -> 617.61 | G25: =D25*F25 -> 66701.88 | J25: 319 | K25: =$K$1 -> 1.19 | L25: =K25*J25 -> 379.61 | M25: =SUM(J25*D25) -> 34452 | N25: 200 | O25: =$O$1 -> 1.19 | P25: =O25*N25 -> 238 | Q25: =SUM(N25*D25) -> 21600
A26: 25 | B26: 220 260924 | C26: Kabelový rošt šíře 40cm (mont. vč. základního i instalačního materiálu) | D26: 4 | E26: m | F26: =L26+P26 -> 916.3 | G26: =D26*F26 -> 3665.2 | J26: 630 | K26: =$K$1 -> 1.19 | L26: =K26*J26 -> 749.7 | M26: =SUM(J26*D26) -> 2520 | N26: 140 | O26: =$O$1 -> 1.19 | P26: =O26*N26 -> 166.6 | Q26: =SUM(N26*D26) -> 560
A27: 26 | B27: 220 261101 | C27: Konstrukce ocelová do 5 kg na m (mont. vč. materiálu) | D27: 96 | E27: ks | F27: =L27+P27 -> 53.55 | G27: =D27*F27 -> 5140.8 | I27: =G27*0.5 -> 2570.4 | J27: 45 | K27: =$K$1 -> 1.19 | L27: =K27*J27 -> 53.55 | M27: =SUM(J27*D27) -> 4320 | O27: =$O$1 -> 1.19 | P27: =O27*N27 -> 0 | Q27: =SUM(N27*D27) -> 0
A28: 27 | B28: 220 261102 | C28: Konstrukce ocelová do 10 kg na m (mont. vč. materiálu) | D28: 216 | E28: ks | F28: =L28+P28 -> 77.35 | G28: =D28*F28 -> 16707.6 | I28: =G28*0.5 -> 8353.8 | J28: 65 | K28: =$K$1 -> 1.19 | L28: =K28*J28 -> 77.35 | M28: =SUM(J28*D28) -> 14040 | O28: =$O$1 -> 1.19 | P28: =O28*N28 -> 0 | Q28: =SUM(N28*D28) -> 0
A29: 28 | B29: 220 261653 | C29: Uchycení ocelové konstrukce beton | D29: 308 | E29: ks | F29: =L29+P29 -> 77.35 | G29: =D29*F29 -> 23823.8 | I29: =G29*0.5 -> 11911.9 | K29: =$K$1 -> 1.19 | L29: =K29*J29 -> 0 | M29: =SUM(J29*D29) -> 0 | N29: 65 | O29: =$O$1 -> 1.19 | P29: =O29*N29 -> 77.35 | Q29: =SUM(N29*D29) -> 20020
A30: 29 | B30: 220 261641 | C30: Osazení hmoždinky 6 mm beton (mont. vč. materiálu) | D30: 78 | E30: ks | F30: =L30+P30 -> 7.14 | G30: =D30*F30 -> 556.92 | I30: =G30*0.5 -> 278.46 | K30: =$K$1 -> 1.19 | L30: =K30*J30 -> 0 | M30: =SUM(J30*D30) -> 0 | N30: 6 | O30: =$O$1 -> 1.19 | P30: =O30*N30 -> 7.14 | Q30: =SUM(N30*D30) -> 468
A31: 30 | B31: 220 261642 | C31: Osazení hmoždinky 8 mm beton (mont. vč. materiálu) | D31: 1020 | E31: ks | F31: =L31+P31 -> 7.14 | G31: =D31*F31 -> 7282.8 | I31: =G31*0.5 -> 3641.4 | K31: =$K$1 -> 1.19 | L31: =K31*J31 -> 0 | M31: =SUM(J31*D31) -> 0 | N31: 6 | O31: =$O$1 -> 1.19 | P31: =O31*N31 -> 7.14 | Q31: =SUM(N31*D31) -> 6120
A32: 31 | B32: 220 261643 | C32: Osazení hmoždinky 10 mm beton (mont. vč. materiálu) | D32: 84 | E32: ks | F32: =L32+P32 -> 8.33 | G32: =D32*F32 -> 699.72 | I32: =G32*0.5 -> 349.86 | K32: =$K$1 -> 1.19 | L32: =K32*J32 -> 0 | M32: =SUM(J32*D32) -> 0 | N32: 7 | O32: =$O$1 -> 1.19 | P32: =O32*N32 -> 8.33 | Q32: =SUM(N32*D32) -> 588
A33: 32 | B33: 220 261644 | C33: Osazení hmoždinky 12 mm beton (mont. vč. materiálu) | D33: 224 | E33: ks | F33: =L33+P33 -> 8.33 | G33: =D33*F33 -> 1865.92 | I33: =G33*0.5 -> 932.96 | K33: =$K$1 -> 1.19 | L33: =K33*J33 -> 0 | M33: =SUM(J33*D33) -> 0 | N33: 7 | O33: =$O$1 -> 1.19 | P33: =O33*N33 -> 8.33 | Q33: =SUM(N33*D33) -> 1568
A34: 33 | B34: 220 730032 | C34: Vyzvednutí stožáru na plochou střechu | D34: 1 | E34: ks | F34: =L34+P34 -> 178.5 | G34: =D34*F34 -> 178.5 | K34: =$K$1 -> 1.19 | L34: =K34*J34 -> 0 | M34: =SUM(J34*D34) -> 0 | N34: 150 | O34: =$O$1 -> 1.19 | P34: =O34*N34 -> 178.5 | Q34: =SUM(N34*D34) -> 150
A35: 34 | B35: 220 730033 | C35: Vyzvednutí soupravy beton. bloků AT | D35: 1 | E35: ks | F35: =L35+P35 -> 357 | G35: =D35*F35 -> 357 | K35: =$K$1 -> 1.19 | L35: =K35*J35 -> 0 | M35: =SUM(J35*D35) -> 0 | N35: 300 | O35: =$O$1 -> 1.19 | P35: =O35*N35 -> 357 | Q35: =SUM(N35*D35) -> 300
A36: 35 | B36: 220 730051 | C36: Stožár AT 1 do kotevní konstrukce (mont. vč. materiálu) | D36: 1 | E36: ks | F36: =L36+P36 -> 178.5 | G36: =D36*F36 -> 178.5 | K36: =$K$1 -> 1.19 | L36: =K36*J36 -> 0 | M36: =SUM(J36*D36) -> 0 | N36: 150 | O36: =$O$1 -> 1.19 | P36: =O36*N36 -> 178.5 | Q36: =SUM(N36*D36) -> 150
A37: 36 | B37: 220 730075 | C37: Kotvení AT 3 do zdi-beton rovná střecha (mont. vč. materiálu) | D37: 1 | E37: ks | F37: =L37+P37 -> 178.5 | G37: =D37*F37 -> 178.5 | K37: =$K$1 -> 1.19 | L37: =K37*J37 -> 0 | M37: =SUM(J37*D37) -> 0 | N37: 150 | O37: =$O$1 -> 1.19 | P37: =O37*N37 -> 178.5 | Q37: =SUM(N37*D37) -> 150
A38: 37 | B38: 210 020922 | C38: Protipož.ucpávka průch.stěnou t= do 30 cm (mont. vč. materiálu) | D38: 0.2 | E38: m2 | F38: =L38+P38 -> 0 | G38: =D38*F38 -> 0 | K38: =$K$1 -> 1.19 | L38: =K38*J38 -> 0 | M38: =SUM(J38*D38) -> 0 | O38: =$O$1 -> 1.19 | P38: =O38*N38 -> 0 | Q38: =SUM(N38*D38) -> 0
A39: 38 | C39: Koordinace zařízení v zárubních či dveřích | D39: 2 | E39: hod | F39: =L39+P39 -> 357 | G39: =D39*F39 -> 714 | K39: =$K$1 -> 1.19 | L39: =K39*J39 -> 0 | M39: =SUM(J39*D39) -> 0 | N39: 300 | O39: =$O$1 -> 1.19 | P39: =O39*N39 -> 357 | Q39: =SUM(N39*D39) -> 600
A40: 39 | C40: Značení kabeláží, tras a rozvaděčů | D40: 1 | E40: kpl | F40: =L40+P40 -> 1785 | G40: =D40*F40 -> 1785 | K40: =$K$1 -> 1.19 | L40: =K40*J40 -> 0 | M40: =SUM(J40*D40) -> 0 | N40: 1500 | O40: =$O$1 -> 1.19 | P40: =O40*N40 -> 1785 | Q40: =SUM(N40*D40) -> 1500
...
