Workbook

Sheet Rekapitulace
A1: Název | B1: Hodnota A | C1: Hodnota B
A2: Základní náklady
A3: Dodávka | B3: =0 -> 0
A4: Doprava 0,00%, Přesun 1,00% | B4: =B3 * Parametry!B16 / 100 -> 0 | C4: =B3 * Parametry!B17 / 100 -> 0
A5: Montáž - materiál | C5: =(Rozpočet!F105) + 0 -> 0
A6: Montáž - práce | C6: =0 + (Rozpočet!H105) + 0 -> 0
A7: Mezisoučet 1 | B7: =B3 + B4 -> 0 | C7: =C3 + C4 + C5 + C6 -> 0
A8: PPV 1,00% z montáže: materiál + práce | C8: =(C5 + C6) * Parametry!B18 / 100 -> 0
A9: Nátěry | C9: =0 + 0 -> 0
A10: Zemní práce | C10: =(Rozpočet!F145) + (Rozpočet!H145) -> 0
A11: PPV 0,00% z nátěrů a zemních prací | C11: =(C9 + C10) * Parametry!B19 / 100 -> 0
A12: Mezisoučet 2 | B12: =B7 -> 0 | C12: =C7 + C8 + C9 + C10 + C11 -> 0
A13: Dodav. dokumentace 0,00% z mezisoučtu 2 | C13: =(B12 + C12) * Parametry!B20 / 100 -> 0
A14: Rizika a pojištění 0,00% z mezisoučtu 2 | C14: =(B12 + C12) * Parametry!B21 / 100 -> 0
A15: Opravy v záruce 0,00% z mezisoučtu 1 | C15: =(B7 + C7) * Parametry!B22 / 100 -> 0
A16: Základní náklady celkem | C16: =B12 + C12 + C13 + C14 + C15 -> 0
A18: Vedlejší náklady
A19: GZS 3,25% z pravé strany mezisoučtu 2 | C19: =C12 * Parametry!B23 / 100 -> 0
A20: Provozní vlivy 0,00% z pravé strany mezisoučtu 2 | C20: =C12 * Parametry!B24 / 100 -> 0
A21: Vedlejší náklady celkem | C21: =C19 + C20 -> 0
A22: Kompletační činnost | C22: =Parametry!B25 * Parametry!B28 * (C16 * Parametry!B27)^Parametry!B26 -> 0
A24: Náklady celkem bez DPH | C24: =C16 + C21 + C22 -> 0
A26: Součty odstavců | B26: Materiál | C26: Montáž
A27: Elektromontáže | B27: =(Rozpočet!F105) -> 0 | C27: =(Rozpočet!H105) -> 0
A28: D.2.5.1 - SO31 Areálové rozvody NN a VO | B28: =(Rozpočet!F102) -> 0 | C28: =(Rozpočet!H102) -> 0
A29: Svítidla | B29: =(Rozpočet!F12) -> 0 | C29: =(Rozpočet!H12) -> 0
A30: Sloupy VO | B30: =(Rozpočet!F23) -> 0 | C30: =(Rozpočet!H23) -> 0
A31: Kabely | B31: =(Rozpočet!F35) -> 0 | C31: =(Rozpočet!H35) -> 0
A32: Kabelové trasy, nosné konstrukce | B32: =(Rozpočet!F43) -> 0 | C32: =(Rozpočet!H43) -> 0
A33: Ukončení vodičů | B33: =(Rozpočet!F60) -> 0 | C33: =(Rozpočet!H60) -> 0
A34: Uzemnění | B34: =(Rozpočet!F80) -> 0 | C34: =(Rozpočet!H80) -> 0
A35: Ostatní | B35: =(Rozpočet!F93) -> 0 | C35: =(Rozpočet!H93) -> 0
A36: Revize | B36: =(Rozpočet!F100) -> 0 | C36: =(Rozpočet!H100) -> 0
A37: Zemní práce | B37: =(Rozpočet!F145) -> 0 | C37: =(Rozpočet!H145) -> 0

Sheet Rozpočet
B1: Název | C1: Mj | D1: Počet | E1: Materiál | F1: Materiál celkem | G1: Montáž | H1: Montáž celkem | I1: Cena | J1: Cena celkem | M1: =Parametry!B33/100*F9+Parametry!B33/100*F10+Parametry!B33/100*F17+Parametry!B33/100*F19+Parametry!B33/100*F21+Parametry!B33/100*F28+Parametry!B33/100*F30+Parametry!B33/100*F31+Parametry!B33/100*F32+Parametry!B33/100*F33+Parametry!B33/100*F39+Parametry!B33/100*F40+Parametry!B33/100*F41+Parametry!B33/100*F49+Parametry!B33/100*F50+Parametry!B33/100*F51+Parametry!B33/100*F53+Parametry!B33/100*F54+Parametry!B33/100*F55+Parametry!B33/100*F56+Parametry!B33/100*F57+Parametry!B33/100*F58+Parametry!B34/100*F66 -> 0
I2: =E2+G2 -> 0 | J2: =F2+H2 -> 0
B3: Elektromontáže
I4: =E4+G4 -> 0 | J4: =F4+H4 -> 0
B5: D.2.5.1 - SO31 Areálové rozvody NN a VO
I6: =E6+G6 -> 0 | J6: =F6+H6 -> 0
B7: Svítidla - jen montáž
I8: =E8+G8 -> 0 | J8: =F8+H8 -> 0
B9: CHA1 (X1) -THOME Lighting s.r.o. MOD0007_280W_840_60° MODY 42000lm 280W IP66 4K 60° | C9: ks | D9: 6 | F9: =D9*E9 -> 0 | H9: =D9*G9 -> 0 | I9: =E9+G9 -> 0 | J9: =F9+H9 -> 0
B10: SL002 Poplatek za recyklaci svítidla | C10: ks | D10: 6 | F10: =D10*E10 -> 0 | H10: =D10*G10 -> 0 | I10: =E10+G10 -> 0 | J10: =F10+H10 -> 0
I11: =E11+G11 -> 0 | J11: =F11+H11 -> 0
B12: Svítidla - celkem | F12: =SUM(F8:F11) -> 0 | H12: =SUM(H8:H11) -> 0 | J12: =SUM(J8:J11) -> 0
I13: =E13+G13 -> 0 | J13: =F13+H13 -> 0
B14: Sloupy VO
I15: =E15+G15 -> 0 | J15: =F15+H15 -> 0
B16: OSVĚTLOVACÍ STOŽÁR BEZPATICOVÝ
B17: JBUD14 14m, stožár silniční, bezpaticový, s přírubou | C17: ks | D17: 3 | F17: =D17*E17 -> 0 | H17: =D17*G17 -> 0 | I17: =E17+G17 -> 0 | J17: =F17+H17 -> 0
B18: VÝLOŽNÍK
B19: Držák reflektorů, typ TR2-1500-PL (AMAKO) pro dva reflektory | C19: ks | D19: 3 | F19: =D19*E19 -> 0 | H19: =D19*G19 -> 0 | I19: =E19+G19 -> 0 | J19: =F19+H19 -> 0
B20: STOŽÁROVÁ VÝZBROJ
B21: EKM 2035 2xE27, 2x Svorkovnice 4x16 | C21: ks | D21: 3 | F21: =D21*E21 -> 0 | H21: =D21*G21 -> 0 | I21: =E21+G21 -> 0 | J21: =F21+H21 -> 0
I22: =E22+G22 -> 0 | J22: =F22+H22 -> 0
B23: Sloupy VO - celkem | F23: =SUM(F15:F22) -> 0 | H23: =SUM(H15:H22) -> 0 | J23: =SUM(J15:J22) -> 0
I24: =E24+G24 -> 0 | J24: =F24+H24 -> 0
B25: Kabely
I26: =E26+G26 -> 0 | J26: =F26+H26 -> 0
B27: KABEL SILOVÝ,IZOLACE PVC,1kV
B28: AYKY-J 3x120+70 | C28: m | D28: 400 | F28: =D28*E28 -> 0 | H28: =D28*G28 -> 0 | I28: =E28+G28 -> 0 | J28: =F28+H28 -> 0
B29: KABEL SILOVÝ,IZOLACE PVC
B30: CYKY-J 3x1.5 | C30: m | D30: 180 | F30: =D30*E30 -> 0 | H30: =D30*G30 -> 0 | I30: =E30+G30 -> 0 | J30: =F30+H30 -> 0
B31: CYKY-J 4x10 | C31: m | D31: 550 | F31: =D31*E31 -> 0 | H31: =D31*G31 -> 0 | I31: =E31+G31 -> 0 | J31: =F31+H31 -> 0
B32: CYKY-J 5x10 | C32: m | D32: 110 | F32: =D32*E32 -> 0 | H32: =D32*G32 -> 0 | I32: =E32+G32 -> 0 | J32: =F32+H32 -> 0
B33: CYKY-J 3x4 | C33: m | D33: 150 | F33: =D33*E33 -> 0 | H33: =D33*G33 -> 0 | I33: =E33+G33 -> 0 | J33: =F33+H33 -> 0
I34: =E34+G34 -> 0 | J34: =F34+H34 -> 0
B35: Kabely - celkem | F35: =SUM(F26:F34) -> 0 | H35: =SUM(H26:H34) -> 0 | J35: =SUM(J26:J34) -> 0
I36: =E36+G36 -> 0 | J36: =F36+H36 -> 0
B37: Kabelové trasy, nosné konstrukce
I38: =E38+G38 -> 0 | J38: =F38+H38 -> 0
B39: KF 09110 TRUBKA KOPOFLEX 110 | C39: m | D39: 20 | F39: =D39*E39 -> 0 | H39: =D39*G39 -> 0 | I39: =E39+G39 -> 0 | J39: =F39+H39 -> 0
B40: KF 09160 TRUBKA KOPOFLEX 160 | C40: m | D40: 90 | F40: =D40*E40 -> 0 | H40: =D40*G40 -> 0 | I40: =E40+G40 -> 0 | J40: =F40+H40 -> 0
...

Sheet Parametry
A1: Název | B1: Hodnota
A2: Nadpis rekapitulace | B2: Seznam prací a dodávek elektrotechnických zařízení
A3: Akce | B3: Prodejna pro dům a zahradu, ulice Lomská, Litvínov
A4: Projekt | B4: D.2.5-1 - SO 31 Areálové rozvody NN a VO
A5: Investor | B5: DEKINVEST, investiční fond s proměnným základním kapitálem, a.s. Tiskařská 257/10, 108 00 Praha 10
A6: Z. č. | B6: 2017-15-02
A7: A. č. | B7: 21458
A8: Smlouva
A9: Vypracoval | B9: Martin Zeman
A10: Kontroloval | B10: Martin Zeman
A11: Datum | B11: 13.12.2021
A12: Zpracovatel | B12: Martin Zeman, Zašovská 256, Valašské Meziříčí
A13: CÚ | B13: 12/2021
A14: Poznámka | B14: Uvedené ceny jsou v Kč a nezahrnují DPH, pokud to není uvedeno.
A16: Doprava dodávek (3,6) % | B16: 0,00
A17: Přesun dodávek (1) % | B17: 1,00
A18: PPV (1 nebo 6) % | B18: 1,00
A19: PPV zemních prací, nátěrů (1) % | B19: 0,00
A20: Dodavat. dokumentace (1 - 1,5) % | B20: 0,00
A21: Rizika a pojištění (1 - 1,5) % | B21: 0,00
... A32: 2. sazba DPH % | B32: 15
A33: Procento PM % 1 | B33: 5
A34: Procento PM % 2 | B34: 1
